Workbook

Sheet Entenda a planilha
B2: ABAIXO É EXPLICADO O QUE CONSTA EM CADA ABA DA PLANILHA:
B4: CAIXA
C5: Nesta aba é exibido o valor que consta em cada caixa do Núcleo no último dia do mês, ou seja, o valor em espécie e o valor em cada conta bancária, mês a mês.
B7: DISTRIB. VALORES
C8: Nesta aba mostra como o dinheiro do Núcleo está distribuído, mês a mês, considerando o valor operacional para uso da Tesouraria, Beneficência, Novo Encanto, Plantio, Fundo de Reserva de Bilhete Aéreo e Fundo de Reserva para Construções. É possível visualizar quanto tivemos de receita e despesa para cada linha, bem como o saldo atual.
B10: DINHEIRO
C11: Nesta aba consta a movimentação em dinheiro, mês a mês. Observação: - Quando há um depósito em dinheiro cujo valor sai do caixa em espécie e entra para uma conta bancária do núcleo, irá constar uma despesa nessa aba e uma receita na aba "TRANSF. ENTRE CONTAS". - Quando há um saque de dinheiro de alguma conta bancária do núcleo, irá constar uma receita nessa aba e uma despesa na aba "TRANSF. ENTRE CONTAS".
B13: TRANSF. ENTRE CONTAS
C14: Nesta aba consta a movimentação entre contas bancárias do núcleo, mês a mês. Observação: - Quando há um depósito em dinheiro cujo valor sai do caixa em espécie e entra para uma conta do núcleo, irá constar uma despesa nessa aba e uma receita na aba "TRANSF. ENTRE CONTAS". - Quando há um saque de dinheiro de alguma conta bancária do núcleo, irá constar uma receita nessa aba e uma despesa na aba "TRANSF. ENTRE CONTAS".
B16: ANO-MÊS-RECEITAS
C17: Nesta aba constam todas as receitas do Núcleo no referido mês, indicando a data da receita, se a receita foi efetivada ou não e em qual caixa a receita "entrou". Haverá uma aba desta para cada mês.
B19: ANO-MÊS-DESPESAS
C20: Nesta aba constam todas as despesas do Núcleo no referido mês, indicando a data da despesa, se a receita foi efetivada ou não, a partir de qual caixa a despesa foi paga e o link para acesso ao comprovante. Haverá uma aba desta para cada mês.
B22: INADIMPLÊNCIA
C23: Nesta aba consta a relação dos sócios inadimplentes no momento, bem como os respectivos valores.
B25: ANO-PREVISTO
C26: Nesta aba consta uma visão consolidada de todas as receitas e despesas previstas para o ano, mês a mês, possibilitando obter uma projeção financeira para o Núcleo ao longo do ano.
B28: ANO-REALIZADO
C29: Nesta aba consta uma visão consolidada de todas as receitas e despesas realizadas no ano, mês a mês, possibilitando obter uma visão gerencial da saúde financeira do Núcleo ao longo do ano.
B31: REUNIÃO DE DIRETORIA
C32: Nesta aba consta o material a ser apresentado na reunião de diretoria.

Sheet Caixa
B2: CAIXAS | C2: SALDO FINAL NOV/23
D3: DEZ
B4: Tesouraria | C4: 33064.72 | D4: 15514.56
B5: Dinheiro em espécie | C5: 1076.55 | D5: 3057.2
B6: Banco - Cora | C6: 582.43 | D6: 9212.39
B7: Banco - Pagbank | C7: 31405.74 | D7: 741.96
B8: Banco - Stone | D8: 2496.26
B9: Banco - Ton | D9: 6.75
B11: Observação: Não houve movimentação financeira na conta bancária da TON.

Sheet Distrib. Valores
B2: DISTRIB. VALORES | C2: SALDO ATUAL
D3: DEZ
B4: SALDO | C4: 15514.56 | D4: 601.53
B5: Receita | C5: - | D5: 25865.7
B6: Operacional Tesouraria | C6: 10138.28 | D6: 20062.2
B7: Beneficência NLT | C7: 790.29 | D7: 141.6
B8: Novo Encanto NLT | C8: 1460.81 | D8: 174.4
B9: Plantio NLT | C9: 1527.53 | D9: 130
B10: Fundo de Reserva Bilhete Aéreo | C10: 1597.65 | D10: 235
B11: Fundo de Reserva Construção | C11: 2.910383e-11 | D11: 5122.5
B13: Despesa | C13: - | D13: 25264.17
B14: Operacional Tesouraria | C14: - | D14: 18740.71
B15: Repasse Novo encanto | D15: 114
B16: Repasse Flor Divina | D16: 4203.57
B17: Repasse Memorial José Gabriel da Costa | D17: 0
B18: Beneficência NLT | D18: 100
B19: Novo Encanto NLT | D19: 0
B20: Plantio NLT | D20: 80
B21: Fundo de Reserva Bilhete Aéreo | D21: 0
B22: Fundo de Reserva Construção | D22: 2025.89
B24: Observação:

Sheet Dinheiro
B2: MOV. EM DINHEIRO | C2: SALDO ATUAL
D3: DEZ
B4: SALDO | C4: 3057.2 | D4: -500
B5: Receita | C5: - | D5: 0
B6: Recebimento Mensalidade | D6: 0
B7: 1a Escala - Caixa jantar | D7: 0
B8: 2a Escala - Caixa jantar | D8: 0
B9: 1a Escala - Caixa da boa vontade | D9: 0
B10: 2a Escala - Caixa da boa vontade | D10: 0
B11: Outras receitas | D11: 0
B12: Outras receitas | D12: 0
B13: Promoção | D13: 0
B14: Doação | D14: 0
B16: Despesa | C16: - | D16: 500
B17: Cantina SANA | D17: 0
B18: Cantina SANA | D18: 0
B19: Cantina SANA | D19: 0
B20: Promoção | D20: 0
B21: Outras despesas | D21: 0
B22: Outras despesas | D22: 0
B23: Outras despesas | D23: 0
B24: Depósito | D24: 500
B26: Observações do mês:

Sheet Mov. entre Contas
B2: MOVIM. ENTRE CONTAS
C3: DEZ
B4: SALDO | C4: 500
B5: Entrada | C5: 500
B6: Banco - Cora | C6: 500
B7: Banco - Pagbank | C7: 0
B8: Banco - Stone | C8: 0
B9: Banco - Ton | C9: 0
B11: Saída | C11: 0
B12: Banco - Cora | C12: 0
B13: Banco - Pagbank | C13: 0
B14: Banco - Stone | C14: 0
B15: Banco - Ton | C15: 0
B17: Observações do mês:

Sheet 2023-DEZ-RECEITAS
B2: RECEITAS
B4: TOTAL | E4: =SUM(E6,E127,E147,E166,E170) -> 13054.13 | F4: =SUM(F6,F127,F147,F166,F170) -> 16583.84 | H4: CAIXA | I4: PLANO DE CONTAS DG
C5: Data | D5: Efetivado | E5: Valor Previsto | F5: Valor Recebido | G5: Observação | J5: Inadimp. (qtd) | K5: Inadimp. (R$) | L5: Núcleo | M5: Repasse DG | N5: Repasse 11a R | O5: Benef. NLT | P5: NE NLT | Q5: Plantio NLT | R5: FR Bilhete Aéreo | S5: FR Construção | T5: Taxa Extra | U5: Detalhamento Taxa Extra | W5: A receber:
B6: Mensalidade | C6: 10 | D6: - | E6: =SUM(E7:E126) -> 13054.13 | F6: =SUM(F7:F126) -> 13681.15 | G6: - | J6: =(COUNTIF(D7:D126,"Pendente")+COUNTIF(D7:D126,"Parcial"))/COUNTA(B7:B126) -> 0.13131313 | K6: =IFERROR(-(W6/E6),"Pendente info") -> 0.099068264 | L6: =SUMIF($D$7:$D$126,"OK",L7:L126)+SUMIF($D$7:$D$126,"Parcial",L7:L126) -> 8523.3 | M6: =SUMIF($D$7:$D$126,"OK",M7:M126)+SUMIF($D$7:$D$126,"Parcial",M7:M126) -> 2186.73 | N6: =SUMIF($D$7:$D$126,"OK",N7:N126)+SUMIF($D$7:$D$126,"Parcial",N7:N126) -> 1157 | O6: =SUMIF($D$7:$D$126,"OK",O7:O126)+SUMIF($D$7:$D$126,"Parcial",O7:O126) -> 224.12 | P6: =SUMIF($D$7:$D$126,"OK",P7:P126)+SUMIF($D$7:$D$126,"Parcial",P7:P126) -> 150 | Q6: =SUMIF($D$7:$D$126,"OK",Q7:Q126)+SUMIF($D$7:$D$126,"Parcial",Q7:Q126) -> 295 | R6: =SUMIF($D$7:$D$126,"OK",R7:R126)+SUMIF($D$7:$D$126,"Parcial",R7:R126) -> 390 | S6: =SUMIF($D$7:$D$126,"OK",S7:S126)+SUMIF($D$7:$D$126,"Parcial",S7:S126) -> 705 | T6: =SUMIF($D$7:$D$126,"OK",T7:T126)+SUMIF($D$7:$D$126,"Parcial",T7:T126) -> 50 | U6: - | V6: =IF(F6=SUM(L6:T6),"OK","Diferente") -> OK | W6: =SUM(W7:W126) -> -1293.25
B7: Elpídio Gomes de Moura Neto | C7: 12 | D7: OK | E7: 140.44 | F7: =E7 -> 140.44 | G7: Pagamento único de R$ 445,81 | H7: Banco - Cora | L7: 76.43 | M7: 24.57 | N7: 13 | O7: 1.44 | P7: 5 | Q7: 5 | R7: 15 | V7: =IF(F7=SUM(L7:T7),"OK","Diferente") -> OK | W7: =IF(V7="Diferente",F7-SUM(L7:T7),"")
B8: Juliana Collyer Arruda de Moura | C8: 12 | D8: OK | E8: 101.29 | F8: =E8 -> 101.29 | H8: Banco - Cora | L8: 52.28 | M8: 24.57 | N8: 13 | O8: 1.44 | P8: 5 | Q8: 5 | V8: =IF(F8=SUM(L8:T8),"OK","Diferente") -> OK | W8: =IF(V8="Diferente",F8-SUM(L8:T8),"")
B9: Silvéria Lopes Vasconcelos Arruda | C9: 12 | D9: OK | E9: 91.29 | F9: =E9 -> 91.29 | H9: Banco - Cora | L9: 52.28 | M9: 24.57 | N9: 13 | O9: 1.44 | V9: =IF(F9=SUM(L9:T9),"OK","Diferente") -> OK | W9: =IF(V9="Diferente",F9-SUM(L9:T9),"")
B10: Francisco de Assis Vasconcelos Arruda | C10: 12 | D10: OK | E10: 112.79 | F10: =E10 -> 112.79 | H10: Banco - Cora | L10: 63.78 | M10: 24.57 | N10: 13 | O10: 1.44 | P10: 5 | Q10: 5 | V10: =IF(F10=SUM(L10:T10),"OK","Diferente") -> OK | W10: =IF(V10="Diferente",F10-SUM(L10:T10),"")
B11: Antônio Gonçalves de Lima Filho | C11: 11 | D11: OK | E11: 166.17 | F11: =E11 -> 166.17 | G11: Pagamento único de R$ 312,34 | H11: Banco - Cora | L11: 107.16 | M11: 24.57 | N11: 13 | O11: 1.44 | Q11: 10 | R11: 10 | V11: =IF(F11=SUM(L11:T11),"OK","Diferente") -> OK | W11: =IF(V11="Diferente",F11-SUM(L11:T11),"")
B12: Sandra Borges Gonçalves de Lima | C12: 11 | D12: OK | E12: 146.17 | F12: =E12 -> 146.17 | H12: Banco - Cora | L12: 107.16 | M12: 24.57 | N12: 13 | O12: 1.44 | V12: =IF(F12=SUM(L12:T12),"OK","Diferente") -> OK | W12: =IF(V12="Diferente",F12-SUM(L12:T12),"")
B13: Marcelo de Castro Brasil | D13: Pendente | E13: 296.49 | F13: 0 | L13: 127.48 | M13: 24.57 | N13: 13 | O13: 1.44 | P13: 10 | Q13: 20 | R13: 50 | S13: 50 | V13: =IF(F13=SUM(L13:T13),"OK","Diferente") -> Diferente | W13: =IF(V13="Diferente",F13-SUM(L13:T13),"") -> -296.49
B14: Flora Borges Gonçalves Lima Brasil | D14: Pendente | E14: 189.29 | F14: 0 | L14: 95.28 | M14: 24.57 | N14: 13 | O14: 1.44 | P14: 5 | S14: 50 | V14: =IF(F14=SUM(L14:T14),"OK","Diferente") -> Diferente | W14: =IF(V14="Diferente",F14-SUM(L14:T14),"") -> -189.29
B15: Cássio Pereira Costa Sousa | C15: 19 | D15: OK | E15: 186.14 | F15: =E15*2 -> 372.28 | G15: Pagamento único de R$ 564,26 descontado da despesa de alimentação paga pela C. Mônica referente à confraternização. Desta forma, não há essa entrada no extrato do banco. | H15: Banco - Cora | L15: =117.13+186.14 -> 303.27 | M15: 24.57 | N15: 13 | O15: 1.44 | P15: 5 | Q15: 5 | R15: 20 | V15: =IF(F15=SUM(L15:T15),"OK","Diferente") -> OK | W15: =IF(V15="Diferente",F15-SUM(L15:T15),"")
B16: Mônica de Araújo Campos Costa Sousa | C16: 19 | D16: OK | E16: 95.99 | F16: =E16*2 -> 191.98 | H16: Banco - Cora | L16: =46.98+95.99 -> 142.97 | M16: 24.57 | N16: 13 | O16: 1.44 | P16: 5 | Q16: 5 | V16: =IF(F16=SUM(L16:T16),"OK","Diferente") -> OK | W16: =IF(V16="Diferente",F16-SUM(L16:T16),"")
B17: José Maurício Guimarães Gomes | C17: 8 | D17: OK | E17: 192.19 | F17: =E17 -> 192.19 | G17: Pagamento único de R$ 324,18 | H17: Banco - Cora | L17: 148.18 | M17: 24.57 | N17: 13 | O17: 1.44 | P17: 5 | V17: =IF(F17=SUM(L17:T17),"OK","Diferente") -> OK | W17: =IF(V17="Diferente",F17-SUM(L17:T17),"")
B18: Ticiane Aragão da Silveira Gomes | C18: 8 | D18: OK | E18: 131.99 | F18: =E18 -> 131.99 | H18: Banco - Cora | L18: 92.98 | M18: 24.57 | N18: 13 | O18: 1.44 | V18: =IF(F18=SUM(L18:T18),"OK","Diferente") -> OK | W18: =IF(V18="Diferente",F18-SUM(L18:T18),"")
B19: Sérvulo Sidney Gladius Paiva Pimentel | C19: 1 | D19: OK | E19: 434.29 | F19: =E19 -> 434.29 | G19: Pagamento único de R$ 858,58 | H19: Banco - Cora | L19: 325.28 | M19: 24.57 | N19: 13 | O19: 11.44 | Q19: 10 | S19: 50 | V19: =IF(F19=SUM(L19:T19),"OK","Diferente") -> OK | W19: =IF(V19="Diferente",F19-SUM(L19:T19),"")
B20: Maria Danielly Rios da Silva Paiva | C20: 1 | D20: OK | E20: 424.29 | F20: =E20 -> 424.29 | H20: Banco - Cora | L20: 325.28 | M20: 24.57 | N20: 13 | O20: 1.44 | Q20: 10 | S20: 50 | V20: =IF(F20=SUM(L20:T20),"OK","Diferente") -> OK | W20: =IF(V20="Diferente",F20-SUM(L20:T20),"")
B21: Régis Bezerra Gomes | C21: 1 | D21: OK | E21: 171.99 | F21: =E21 -> 171.99 | G21: Pagamento único de R$ 315,58 | H21: Banco - Cora | L21: 92.98 | M21: 24.57 | N21: 13 | O21: 1.44 | P21: 5 | Q21: 5 | S21: 30 | V21: =IF(F21=SUM(L21:T21),"OK","Diferente") -> OK | W21: =IF(V21="Diferente",F21-SUM(L21:T21),"")
B22: Ana Carolina de Oliveira Martins Gomes | C22: 1 | D22: OK | E22: 143.59 | F22: =E22 -> 143.59 | H22: Banco - Cora | L22: 74.58 | M22: 24.57 | N22: 13 | O22: 1.44 | S22: 30 | V22: =IF(F22=SUM(L22:T22),"OK","Diferente") -> OK | W22: =IF(V22="Diferente",F22-SUM(L22:T22),"")
B23: Lindayana de Souza Florêncio | C23: 21 | D23: OK | E23: 83.34 | F23: =E23*2+50 -> 216.68 | G23: Não consta a entrada destes valores no banco pois foram utilizados para compensar a despesa do auto de natal no valor de R$ 445,56. Esta despesa compensa a mensalidade de dezembro/23 e janeiro/24. | H23: Banco - Cora | L23: =34.33*2 -> 68.66 | M23: =24.57*2 -> 49.14 | N23: 26 | O23: 2.88 | P23: 10 | Q23: 10 | T23: 50 | U23: Confraternização dezembro/23 (antecipado de janeiro). | V23: =IF(F23=SUM(L23:T23),"OK","Diferente") -> OK | W23: =IF(V23="Diferente",F23-SUM(L23:T23),"")
B24: Davi Florêncio de Sousa | C24: 21 | D24: OK | E24: 114.44 | F24: =E24*2 -> 228.88 | H24: Banco - Cora | L24: =50.43*2 -> 100.86 | M24: =24.57*2 -> 49.14 | N24: 26 | O24: 2.88 | P24: 10 | Q24: 10 | S24: 30 | V24: =IF(F24=SUM(L24:T24),"OK","Diferente") -> OK | W24: =IF(V24="Diferente",F24-SUM(L24:T24),"")
B25: Joaquim Garcez de Lima Rocha | D25: Pendente | E25: 160.4 | F25: 0 | L25: 106.39 | M25: 24.57 | N25: 13 | O25: 6.44 | Q25: 10 | V25: =IF(F25=SUM(L25:T25),"OK","Diferente") -> Diferente | W25: =IF(V25="Diferente",F25-SUM(L25:T25),"") -> -160.4
B26: Emília Mesquita Salgueiro Garcez | D26: Pendente | E26: 118.35 | F26: 0 | L26: 79.34 | M26: 24.57 | N26: 13 | O26: 1.44 | V26: =IF(F26=SUM(L26:T26),"OK","Diferente") -> Diferente | W26: =IF(V26="Diferente",F26-SUM(L26:T26),"") -> -118.35
B27: Francisco Saulo Studart Albuquerque | C27: 4 | D27: OK | E27: 150 | F27: 645 | G27: R$ 645 referente a agosto, setembro, outubro e novembro | H27: Banco - Cora | L27: =110.43+(645-150) -> 605.43 | M27: 24.57 | N27: 13 | O27: 2 | V27: =IF(F27=SUM(L27:T27),"OK","Diferente") -> OK | W27: =IF(V27="Diferente",F27-SUM(L27:T27),"")
B28: Franco Costa e Silva | C28: 18 | D28: OK | E28: 205.79 | F28: =E28 -> 205.79 | G28: Pagamento único de R$ 264,58. O valor foi a menor que o padrão da mensalidade pois no mês anterior foi realizado um pagamento a maior, gerando crédito para a mensalidade de dezembro. | H28: Banco - Cora | L28: =106.78-37 -> 69.78 | M28: 24.57 | N28: 13 | O28: 11.44 | P28: 5 | Q28: 5 | R28: 10 | S28: 30 | V28: =IF(F28=SUM(L28:T28),"OK","Diferente") -> Diferente | W28: =IF(V28="Diferente",F28-SUM(L28:T28),"") -> 37
B29: Juliana Soares Monteiro | C29: 18 | D29: Parcial | E29: 195.79 | F29: =264.58-F28 -> 58.79 | H29: Banco - Cora | L29: =106.78-100 -> 6.78 | M29: 24.57 | N29: 13 | O29: 1.44 | P29: 5 | Q29: 5 | R29: 10 | S29: 30 | V29: =IF(F29=SUM(L29:T29),"OK","Diferente") -> Diferente | W29: =IF(V29="Diferente",F29-SUM(L29:T29),"") -> -37
B30: Hugo Uchôa Passos Alencar | C30: 5 | D30: OK | E30: 207.69 | F30: =E30 -> 207.69 | G30: Pagamento único de R$ 364,38 | H30: Banco - Cora | L30: 113.68 | M30: 24.57 | N30: 13 | O30: 1.44 | P30: 5 | Q30: 10 | R30: 10 | S30: 30 | V30: =IF(F30=SUM(L30:T30),"OK","Diferente") -> OK | W30: =IF(V30="Diferente",F30-SUM(L30:T30),"")
B31: Mairi Alencar de Lacerda Ferraz Uchôa | C31: 5 | D31: OK | E31: 156.69 | F31: =E31 -> 156.69 | H31: Banco - Cora | L31: 67.68 | M31: 24.57 | N31: 13 | O31: 1.44 | Q31: 10 | R31: 10 | S31: 30 | V31: =IF(F31=SUM(L31:T31),"OK","Diferente") -> OK | W31: =IF(V31="Diferente",F31-SUM(L31:T31),"")
B32: João Carlos Studart Antero | D32: Pendente | E32: 123.99 | F32: 0 | L32: 69.98 | M32: 24.57 | N32: 13 | O32: 1.44 | P32: 5 | R32: 10 | V32: =IF(F32=SUM(L32:T32),"OK","Diferente") -> Diferente | W32: =IF(V32="Diferente",F32-SUM(L32:T32),"") -> -123.99
B33: Janaina Silva Leitão Studart Antero | D33: Pendente | E33: 118.99 | F33: 0 | L33: 69.98 | M33: 24.57 | N33: 13 | O33: 1.44 | R33: 10 | V33: =IF(F33=SUM(L33:T33),"OK","Diferente") -> Diferente | W33: =IF(V33="Diferente",F33-SUM(L33:T33),"") -> -118.99
B34: Janaina de Pádua Carneiro Vasconcelos Giffoni | C34: 12 | D34: OK | E34: 172.79 | F34: =E34 -> 172.79 | G34: Pagamento único de R$ 403,53 | H34: Banco - Cora | L34: 83.78 | M34: 24.57 | N34: 13 | O34: 1.44 | S34: 50 | V34: =IF(F34=SUM(L34:T34),"OK","Diferente") -> OK | W34: =IF(V34="Diferente",F34-SUM(L34:T34),"")
B35: Vicente Alves Giffoni | C35: 12 | D35: OK | E35: 230.74 | F35: =E35 -> 230.74 | H35: Banco - Cora | L35: 121.73 | M35: 24.57 | N35: 13 | O35: 11.44 | Q35: 10 | S35: 50 | V35: =IF(F35=SUM(L35:T35),"OK","Diferente") -> OK | W35: =IF(V35="Diferente",F35-SUM(L35:T35),"")
B36: Raphael Bruno Dantas Moreira | C36: 15 | D36: OK | E36: 196.2 | F36: =E36 -> 196.2 | H36: Banco - Cora | L36: 128.63 | M36: 24.57 | N36: 13 | O36: 10 | P36: 5 | Q36: 15 | V36: =IF(F36=SUM(L36:T36),"OK","Diferente") -> OK | W36: =IF(V36="Diferente",F36-SUM(L36:T36),"")
B37: Davi Silvino Moraes | C37: 2 | D37: OK | E37: 176.76 | F37: =E37 -> 176.76 | H37: Banco - Cora | L37: 79.19 | M37: 24.57 | N37: 13 | O37: 5 | P37: 5 | Q37: 10 | R37: 10 | S37: 30 | V37: =IF(F37=SUM(L37:T37),"OK","Diferente") -> OK | W37: =IF(V37="Diferente",F37-SUM(L37:T37),"")
B38: Dimaranje José Moraes | C38: 15 | D38: OK | E38: 110.81 | F38: =(271/2)+E38 -> 246.31 | G38: Pagamento único de R$ 271,00 referente a novembro. Pagamento único de R$ 221,62 referente a dezembro. | H38: Banco - Cora | L38: =71.74+135.5 -> 207.24 | M38: 24.57 | N38: 13 | O38: 1.5 | V38: =IF(F38=SUM(L38:T38),"OK","Diferente") -> OK | W38: =IF(V38="Diferente",F38-SUM(L38:T38),"")
B39: Silvane da Silva Gonçalves | C39: 15 | D39: OK | E39: 110.81 | F39: =(271/2)+E39 -> 246.31 | H39: Banco - Cora | L39: =71.74+135.5 -> 207.24 | M39: 24.57 | N39: 13 | O39: 1.5 | V39: =IF(F39=SUM(L39:T39),"OK","Diferente") -> OK | W39: =IF(V39="Diferente",F39-SUM(L39:T39),"")
B40: Vicente de Paula Giffoni Filho | C40: 1 | D40: OK | E40: 118.59 | F40: =E40 -> 118.59 | G40: Pagamento único de R$ 428,36 | H40: Banco - Cora | L40: 74.58 | M40: 24.57 | N40: 13 | O40: 1.44 | Q40: 5 | V40: =IF(F40=SUM(L40:T40),"OK","Diferente") -> OK | W40: =IF(V40="Diferente",F40-SUM(L40:T40),"")
B41: Francinete Alves de Oliveira Giffoni | C41: 1 | D41: OK | E41: 123.59 | F41: =E41 -> 123.59 | H41: Banco - Cora | L41: 74.58 | M41: 24.57 | N41: 13 | O41: 1.44 | P41: 5 | Q41: 5 | V41: =IF(F41=SUM(L41:T41),"OK","Diferente") -> OK | W41: =IF(V41="Diferente",F41-SUM(L41:T41),"")
B42: Emanuel Alves Giffoni | C42: 1 | D42: OK | E42: 118.59 | F42: =E42 -> 118.59 | H42: Banco - Cora | L42: 74.58 | M42: 24.57 | N42: 13 | O42: 1.44 | Q42: 5 | V42: =IF(F42=SUM(L42:T42),"OK","Diferente") -> OK | W42: =IF(V42="Diferente",F42-SUM(L42:T42),"")
...

Sheet 2023-DEZ-DESPESAS
B2: DESPESAS
B4: TOTAL | C4: - | D4: - | E4: =SUBTOTAL(9,E12,E37,E24,E105,E130,E136,E43,E6,E20,E192,E233,E142,E152,E162,E172,E182,E58) -> 0 | F4: =SUBTOTAL(9,F12,F37,F24,F95,F105,F130,F136,F43,F6,F20,F192,F233,F142,F152,F162,F172,F182,F58) -> 20359.32 | G4: - | H4: CAIXA | I4: COMPROVANTE | J4: PLANO DE CONTAS DG
C5: Data | D5: Efetivado | E5: Valor Previsto | F5: Valor Pago | G5: Observação
B6: NCL - Funcionários | C6: - | D6: - | E6: =SUM(E7:E11) -> 0 | F6: =SUM(F7:F11) -> 2464.52
B7: Salário | C7: 1 29 | D7: OK | E7: 0 | F7: =669.38+669.38 -> 1338.76 | G7: 01/12: Competência novembro, pago em dezembro. 29/12: Competência dezembro, pago em dezembro. | H7: Banco - Cora | I7: https://drive.google.com/file/d/1hy0gmUuDzO0Y1v2o5JeNrihBy4VZhOXk/view?usp=drive_link https://drive.google.com/file/d/1lH1HF_Pjg1fP995oUndkHiEUbdCEk4Lt/view?usp=drive_link
B8: 13° salário | C8: 20 | D8: OK | E8: 0 | F8: 325.99 | G8: 2a parcela 13° salário | H8: Banco - Cora | I8: https://drive.google.com/file/d/1HxfPZMes6T4DpkfQ9SN_bQakL0wH2ONT/view?usp=drive_link
B9: Férias | E9: 0 | F9: 0
B10: Encargos sociais | C10: 6 6 6 6 11 | D10: OK | E10: 0 | F10: =263.06+40.12+92.04+11.51+263.06 -> 669.79 | G10: 06/12: Darf previdenciário (R$ 263,06) 06/12: Darf previdenciário complementar (R$ 40,12) 06/12: FGTS (R$ 92,04) 06/12: PIS (R$ 11,51) 11/12: Darf previdenciário 13° salário (R$ 263,06) | H10: Banco - Cora | I10: https://drive.google.com/file/d/1K6wk-3aiUDrSIcQpIg07SrxvPGrFP-DY/view?usp=drive_link
B11: Outras despesas | C11: 22 | D11: OK | E11: 0 | F11: 129.98 | G11: 22/12: Duas cestas básicas para o Wesley. Dezembro/23 e janeiro/24. | H11: Banco - Cora | I11: https://drive.google.com/file/d/1armK0m59uAYu4CUS54qTVAiGc4D58WRv/view?usp=drive_link
B12: NCL - Repasses | C12: - | D12: - | E12: =SUM(E13:E19) -> 0 | F12: =SUM(F13:F19) -> 5194.16
B13: Diretoria Geral | C13: 20 | D13: OK | E13: 0 | F13: 2432.43 | H13: Banco - Prosperar Bank | I13: https://drive.google.com/file/d/1cArE6avLBdLZ_P5rT3rm_SHq9NEZyHHr/view?usp=drive_link
B14: 11a Região | C14: 14 | D14: OK | E14: 0 | F14: 1597 | H14: Banco - Prosperar Bank | I14: https://drive.google.com/file/d/16meczPDHPc1QEuGSscL4d7D707LYwmfm/view?usp=drive_link
B15: Novo Encanto | C15: 1 | D15: OK | E15: 0 | F15: 75 | H15: Banco - Cora | I15: https://drive.google.com/file/d/1cHkb8Yo3pPerc3nasiot9hJr4l1NKzRr/view?usp=drive_link
B16: Flor Divina | C16: 29 | D16: OK | E16: 0 | F16: =1089.73 -> 1089.73 | G16: Realizada uma transferência única de R$ 1.134,87, tendo R$ 1.089,73 saído do caixa da tesouraria e R$ 45,14 saído do caixa do Plantio (este valor está registrado nas despesas do plantio). | H16: Banco - Cora | I16: https://drive.google.com/file/d/1Ze8pvPmSyC-jJebtaDGmWRAVg1EjtwxZ/view?usp=drive_link
B17: Outro repasse (1) | E17: 0 | F17: 0
B18: Outro repasse (2) | E18: 0 | F18: 0
B19: Outro repasse (3) | E19: 0 | F19: 0
B20: NCL - Tarifas bancárias | C20: - | D20: - | E20: =SUM(E21:E23) -> 0 | F20: =SUM(F21:F23) -> 185.83
B21: Tarifa Itaú | C21: 4 | D21: OK | E21: 0 | F21: 118 | H21: Banco - Itaú | I21: https://drive.google.com/file/d/1Lrvz77hCs-9Ap-_hYtGDYxki1G3ANRlg/view?usp=drive_link
B22: IR do rendimento bruto do Pagbank | C22: 3 a 23 | D22: OK | E22: 0 | F22: 67.83 | H22: Banco - Pagbank | I22: https://drive.google.com/file/d/11LttsR061P4v40YjP52xj6kuSFCfOTYi/view?usp=drive_link
B23: Tarifa 3 | E23: 0 | F23: 0
B24: NCL - Despesas gerais | C24: - | D24: - | E24: =SUM(E25:E36) -> 0 | F24: =SUM(F25:F36) -> 4146.94
B25: Energia Elétrica | C25: 20 | D25: OK | E25: 0 | F25: 990.95 | H25: Banco - Prosperar Bank | I25: https://drive.google.com/file/d/19M0xZrZjCQjoBB2X8KbSUNgdb2ElEME8/view?usp=sharing
B26: Vigilância - Banco | C26: 17 | D26: OK | E26: 0 | F26: =590 -> 590 | G26: 17/12: R$ 590 referente a 2a escala. | H26: Banco - Cora | I26: https://drive.google.com/file/d/1-wYPjr9-RuWpx8mwPbBKgbEW_-ao1nJ2/view?usp=drive_link
B27: Contabilidade | C27: 4 | D27: OK | E27: 0 | F27: 396 | H27: Banco - Cora | I27: https://drive.google.com/file/d/1upTOtwJrjO-9QEwX0pEf6Xu4dDw0VTRX/view?usp=drive_link
B28: Internet | C28: 1 | D28: OK | E28: 0 | F28: 79.99 | H28: Banco - Cora | I28: https://drive.google.com/file/d/154fyTE2hE2-eF-mYvbl4PsFrIA4CvEBh/view?usp=drive_link
B29: Som | E29: 0 | F29: 0
B30: Jardim | E30: 0 | F30: 0
B31: Aluguel cadeiras 2a escala e sessão extra M. Herculano | C31: 18 | D31: OK | E31: 0 | F31: 200 | H31: Banco - Cora | I31: https://drive.google.com/file/d/1XNnx8OvJv3e9g5t7kDyG_22UT3Gy9hE9/view?usp=drive_link
B32: Compra de calças brancas e amarelas M. Herculano | C32: 19 | D32: OK | E32: 0 | F32: 800 | H32: Banco - Cora | I32: https://drive.google.com/file/d/1I6z53UUGdn_2WHC0Wbf8Uboov-m0h4Gh/view?usp=drive_link
B33: Homenagem M. Herculano | C33: 21 | D33: OK | E33: 0 | F33: 290 | H33: Banco - Cora | I33: https://drive.google.com/file/d/1jqskAC3ezP8yULTHgRoYQmbM6N641kMA/view?usp=drive_link
B34: Vigilância - Espécie | C34: 31 | D34: OK | E34: 0 | F34: 800 | G34: 31/12: R$ 800 referente a sessão de ano novo. | H34: Dinheiro em espécie | I34: https://drive.google.com/file/d/1P-zr1Ezy8pcmrVnt_qoETRI434kGz9Bv/view?usp=drive_link
B35: Despesa 5 | E35: 0 | F35: 0
B36: Despesa 6 | E36: 0 | F36: 0
B37: NCL - Organ | C37: - | D37: - | E37: =SUM(E38:E42) -> 0 | F37: =SUM(F38:F42) -> 2855.32
B38: Mercado | C38: 2 15 17 17 17 22 | D38: OK | E38: 0 | F38: =194.36+323.77+99+51.76+195.87+60 -> 924.76 | G38: 02/12: Despesa lanche compras realizadas pela C. Ticiane (R$ 194,36) 15/12: Despesa lanche compras realizadas pela C. Mônica (R$ 323,77) 17/12: Despesa sucos realizadas pela C. Mônica (R$ 99,00) 17/12: Despesa pães realizadas pela C. Mônica (R$ 51,76) 17/12: Despesa lanche pós sessão realizadas pela C. Mônica (R$ 195,87) 22/12: Despesa milhos realizada pela Genilda (R$ 60,00). Valor compensado em gasolina. | H38: Banco - Cora | I38: https://drive.google.com/file/d/1qohA5ZqkXdAGAMBL9jPLCmu8490VWIKK/view?usp=drive_link https://drive.google.com/file/d/1FimwTgXc5cQaAAXqpNbxTZQ5KHiZTdnC/view?usp=drive_link https://drive.google.com/file/d/1UxUwTwLslc6eMcGDWQDeEAC7cY_apPPj/view?usp=drive_link https://drive.google.com/file/d/1FVP9SX6TRCPgAC27SHwM1qTxya69rkaN/view?usp=drive_link https://drive.google.com/file/d/1vbz-0wRkX3s6zyqn-g6Mu60pchC2vKN3/view?usp=drive_link https://drive.google.com/file/d/1NpttEIh0DeYQy-fFYDCiY2BOfVJw1uMu/view?usp=drive_link
B39: Água mineral | C39: 6 | D39: OK | E39: 0 | F39: =176 -> 176 | G39: 06/12: Compra de água mineral realizada pela C. Mônica (R$ 176,00) | H39: Banco - Prosperar Bank | I39: https://drive.google.com/file/d/1_jNZMYCrAGGWzhMBq9-LhIw9GpW9Czv-/view?usp=drive_link
B40: Jantar | C40: 1 2 15 | D40: OK | E40: 0 | F40: =344.38+54.52+471.89+35.94 -> 906.73 | G40: 01/12: Despesa jantar compras realizadas pela Janaina (R$ 344,38) 02/12: Despesa jantar compras realizadas pela Janaina (R$ 54,52) 15/12: Despesa jantar compras realizadas pela C. Mônica (R$ 471,89) 18/12: Despesa jantar compras realizadas pela C. Mônica (R$ 35,94) | H40: Banco - Cora | I40: https://drive.google.com/file/d/1nPgegJSuqnwuk-iYFRhXYHo8wTC8aEz9/view?usp=drive_link https://drive.google.com/file/d/1sRWeeKtrGlKQTITRH-yqV0m_hkcXNgii/view?usp=drive_link https://drive.google.com/file/d/1x9MFphbftZkHDMhlobbkfb6HuGUDHzNt/view?usp=drive_link https://drive.google.com/file/d/1zRm9goP6Ggpm_QObPvcdrIUpZEEYidEP/view?usp=drive_link
B41: Material de limpeza | C41: 3 5 15 30 | D41: OK | E41: 0 | F41: =40+345.8+173.44+243.6+9.99 -> 812.83 | G41: 03/12: Material de limpeza compras realizadas pelo Didi (R$ 40,00) 05/12: Material de limpeza compras realizadas pela C. Mônica (R$ 345,80) 15/12: Material de limpeza compras realizadas pela C. Mônica (R$ 173,44) 30/12: Material de limpeza compras realizadas pela C. Mônica (R$ 243,60 + R$ 9,99) | H41: Banco - Cora | I41: https://drive.google.com/file/d/1xJLqU67vj9QoDtu5M4sDg3TwvPlUd5Sp/view?usp=drive_link https://drive.google.com/file/d/12kj-Bqazy502velNLugU1ASuF7W7G2mr/view?usp=drive_link https://drive.google.com/file/d/1puaDbpAwNB8jJhxFDy9XPv-19RGucxbz/view?usp=drive_link https://drive.google.com/file/d/1XJXpsoBSrRqg7Yb5ZjlIUeaILjYtuxrx/view?usp=drive_link
B42: Outra despesa (3) | C42: 31 | D42: OK | E42: 0 | F42: 35 | G42: 31/12: Despesa castanhas pós sessão realizada pela C. Mônica (R$ 35,00) | H42: Dinheiro em espécie | I42: https://drive.google.com/file/d/1-8_zDpcbXg1Q9ElAhbCwiAwIGBZzl8r3/view?usp=drive_link
...

Sheet JAN-Receitas
B2: RECEITAS
B4: TOTAL | E4: =SUM(E6,E127,E148,E168,E172) -> 17447.43 | F4: =SUM(F6,F127,F148,F168,F172) -> 49292.99 | H4: CAIXA | I4: PLANO DE CONTAS DG
C5: Data | D5: Efetivado | E5: Valor Previsto | F5: Valor Recebido | G5: Observação | J5: Inadimp. (qtd) | K5: Inadimp. (R$) | L5: % Atraso | M5: Núcleo | N5: Repasse DG | O5: Repasse 11a R | P5: Benef. NLT | Q5: NE NLT | R5: Plantio NLT | S5: FR Bilhete Aéreo | T5: FR Construção | U5: Taxa Extra | V5: Detalhamento Taxa Extra | X5: A receber:
B6: Mensalidade | C6: 10 | D6: - | E6: =SUM(E7:E126) -> 17447.43 | F6: =SUMIF(D7:D126,"OK",F7:F126)+SUMIF(D7:D126,"Parcial",F7:F126) -> 13383.98 | G6: - | J6: =(COUNTIF(D7:D126,"Pendente")+COUNTIF(D7:D126,"Parcial"))/COUNTA(B7:B126) -> 0.31632653 | K6: =IFERROR(-(X6/E6),"Pendente info") -> 0.25623029 | L6: =SUM(L7:L105)/COUNTA(B7:B105) -> 0.19387755 | M6: =SUMIF($D$7:$D$126,"OK",M7:M126)+SUMIF($D$7:$D$126,"Parcial",M7:M126) -> 7065 | N6: =SUMIF($D$7:$D$126,"OK",N7:N126)+SUMIF($D$7:$D$126,"Parcial",N7:N126) -> 1621.62 | O6: =SUMIF($D$7:$D$126,"OK",O7:O126)+SUMIF($D$7:$D$126,"Parcial",O7:O126) -> 792 | P6: =SUMIF($D$7:$D$126,"OK",P7:P126)+SUMIF($D$7:$D$126,"Parcial",P7:P126) -> 152.36 | Q6: =SUMIF($D$7:$D$126,"OK",Q7:Q126)+SUMIF($D$7:$D$126,"Parcial",Q7:Q126) -> 155 | R6: =SUMIF($D$7:$D$126,"OK",R7:R126)+SUMIF($D$7:$D$126,"Parcial",R7:R126) -> 185 | S6: =SUMIF($D$7:$D$126,"OK",S7:S126)+SUMIF($D$7:$D$126,"Parcial",S7:S126) -> 217 | T6: =SUMIF($D$7:$D$126,"OK",T7:T126)+SUMIF($D$7:$D$126,"Parcial",T7:T126) -> 580 | U6: =SUMIF($D$7:$D$126,"OK",U7:U126)+SUMIF($D$7:$D$126,"Parcial",U7:U126) -> 2616 | V6: - | W6: =IF(F6=SUM(M6:U6),"OK","Diferente") -> OK | X6: =SUM(X7:X126) -> -4470.56
B7: ELPÍDIO GOMES DE MOURA NETO | D7: OK | E7: =SUM(M7:U7) -> 0 | L7: =IF(C7>=13,1,"") | V7: TAXA CONFRATERNIZAÇÃO 2024 R$ 5,00; TAXA DE PREPARO 1/2 R$ 13,00 | W7: =IF(F7=SUM(M7:U7),"OK","Diferente") -> OK | X7: =IF(W7="Diferente",F7-SUM(M7:U7),"")
B8: JULIANA COLLYER ARRUDA DE MOURA | D8: OK | E8: =SUM(M8:U8) -> 0 | L8: =IF(C8>=13,1,"") | V8: TAXA CONFRATERNIZAÇÃO 2024 R$ 5,00; TAXA DE PREPARO 1/2 R$ 13,00 | W8: =IF(F8=SUM(M8:U8),"OK","Diferente") -> OK | X8: =IF(W8="Diferente",F8-SUM(M8:U8),"")
B9: SILVERIA LOPES VASCONCELOS ARRUDA | D9: OK | E9: =SUM(M9:U9) -> 0 | L9: =IF(C9>=13,1,"") | V9: TAXA CONFRATERNIZAÇÃO 2024 R$ 5,00; TAXA DE PREPARO 1/2 R$ 13,00 | W9: =IF(F9=SUM(M9:U9),"OK","Diferente") -> OK | X9: =IF(W9="Diferente",F9-SUM(M9:U9),"")
B10: FRANCISCO DE ASSIS VASCONCELOS ARRUDA | D10: OK | E10: =SUM(M10:U10) -> 0 | L10: =IF(C10>=13,1,"") | V10: TAXA CONFRATERNIZAÇÃO 2024 R$ 5,00; TAXA DE PREPARO 1/2 R$ 13,00 | W10: =IF(F10=SUM(M10:U10),"OK","Diferente") -> OK | X10: =IF(W10="Diferente",F10-SUM(M10:U10),"")
B11: ANTÔNIO GONÇALVES DE LIMA FILHO | C11: 10 | D11: OK | E11: =SUM(M11:U11) -> 193.43 | F11: =E11 -> 193.43 | H11: Banco - Cora | L11: =IF(C11>=13,1,"") | M11: 130 | N11: 24.57 | O11: 12 | P11: 3.86 | Q11: 5 | U11: 18 | V11: TAXA CONFRATERNIZAÇÃO 2024 R$ 5,00; TAXA DE PREPARO 1/2 R$ 13,00 | W11: =IF(F11=SUM(M11:U11),"OK","Diferente") -> OK | X11: =IF(W11="Diferente",F11-SUM(M11:U11),"")
B12: SANDRA BORGES GONÇALVES DE LIMA | C12: 10 | D12: OK | E12: =SUM(M12:U12) -> 186.57 | F12: =E12 -> 186.57 | H12: Banco - Cora | L12: =IF(C12>=13,1,"") | M12: 130 | N12: 24.57 | O12: 12 | P12: 2 | U12: 18 | V12: TAXA CONFRATERNIZAÇÃO 2024 R$ 5,00; TAXA DE PREPARO 1/2 R$ 13,00 | W12: =IF(F12=SUM(M12:U12),"OK","Diferente") -> OK | X12: =IF(W12="Diferente",F12-SUM(M12:U12),"")
B13: MARCELO DE CASTRO BRASIL | D13: Pendente | E13: =SUM(M13:U13) -> 366.49 | L13: =IF(C13>=13,1,"") | M13: 130.48 | N13: 24.57 | O13: 12 | P13: 1.44 | Q13: 10 | R13: 20 | S13: 50 | T13: 50 | U13: 68 | V13: COMPRA DE ARCONDICIONADO 7/10 R$ 50,00; TAXA CONFRATERNIZAÇÃO 2024 R$ 5,00; TAXA DE PREPARO 1/2 R$ 13,00 | W13: =IF(F13=SUM(M13:U13),"OK","Diferente") -> Diferente | X13: =IF(W13="Diferente",F13-SUM(M13:U13),"") -> -366.49
B14: FLORA BORGES GONÇALVES LIMA BRASIL | D14: Pendente | E14: =SUM(M14:U14) -> 209.29 | L14: =IF(C14>=13,1,"") | M14: 98.28 | N14: 24.57 | O14: 12 | P14: 1.44 | Q14: 5 | T14: 50 | U14: 18 | V14: TAXA CONFRATERNIZAÇÃO 2024 R$ 5,00; TAXA DE PREPARO 1/2 R$ 13,00 | W14: =IF(F14=SUM(M14:U14),"OK","Diferente") -> Diferente | X14: =IF(W14="Diferente",F14-SUM(M14:U14),"") -> -209.29
B15: CÁSSIO PEREIRA COSTA SOUSA | D15: Pendente | E15: =SUM(M15:U15) -> 316.14 | L15: =IF(C15>=13,1,"") | M15: 180.13 | N15: 24.57 | O15: 12 | P15: 1.44 | Q15: 5 | R15: 5 | S15: 20 | U15: 68 | V15: COMPRA DE ARCONDICIONADO 7/10 R$ 50,00; TAXA CONFRATERNIZAÇÃO 2024 R$ 5,00; TAXA DE PREPARO 1/2 R$ 13,00 | W15: =IF(F15=SUM(M15:U15),"OK","Diferente") -> Diferente | X15: =IF(W15="Diferente",F15-SUM(M15:U15),"") -> -316.14
B16: MÔNICA DE ARAUJO CAMPOS COSTA SOUSA | D16: Pendente | E16: =SUM(M16:U16) -> 155.99 | L16: =IF(C16>=13,1,"") | M16: 89.98 | N16: 24.57 | O16: 12 | P16: 1.44 | Q16: 5 | R16: 5 | U16: 18 | V16: TAXA CONFRATERNIZAÇÃO 2024 R$ 5,00; TAXA DE PREPARO 1/2 R$ 13,00 | W16: =IF(F16=SUM(M16:U16),"OK","Diferente") -> Diferente | X16: =IF(W16="Diferente",F16-SUM(M16:U16),"") -> -155.99
B17: JOSÉ MAURÍCIO GUIMARÃES GOMES | C17: 10 | D17: OK | E17: =SUM(M17:U17) -> 252.19 | F17: =E17 -> 252.19 | H17: Banco - Cora | L17: =IF(C17>=13,1,"") | M17: 191.18 | N17: 24.57 | O17: 12 | P17: 1.44 | Q17: 5 | U17: 18 | V17: TAXA CONFRATERNIZAÇÃO 2024 R$ 5,00; TAXA DE PREPARO 1/2 R$ 13,00 | W17: =IF(F17=SUM(M17:U17),"OK","Diferente") -> OK | X17: =IF(W17="Diferente",F17-SUM(M17:U17),"")
B18: TICIANE ARAGAO DA SILVEIRA GOMES | C18: 10 | D18: OK | E18: =SUM(M18:U18) -> 191.99 | F18: =E18 -> 191.99 | H18: Banco - Cora | L18: =IF(C18>=13,1,"") | M18: 135.98 | N18: 24.57 | O18: 12 | P18: 1.44 | U18: 18 | V18: TAXA CONFRATERNIZAÇÃO 2024 R$ 5,00; TAXA DE PREPARO 1/2 R$ 13,00 | W18: =IF(F18=SUM(M18:U18),"OK","Diferente") -> OK | X18: =IF(W18="Diferente",F18-SUM(M18:U18),"")
B19: SERVULO SIDNEY GLADIUS PAIVA PIMENTEL | C19: 9 | D19: OK | E19: =SUM(M19:U19) -> 459.29 | F19: =E19 -> 459.29 | H19: Banco - Cora | L19: =IF(C19>=13,1,"") | M19: 328.28 | N19: 24.57 | O19: 12 | P19: 11.44 | Q19: 5 | R19: 10 | T19: 50 | U19: 18 | V19: TAXA CONFRATERNIZAÇÃO 2024 R$ 5,00; TAXA DE PREPARO 1/2 R$ 13,00 | W19: =IF(F19=SUM(M19:U19),"OK","Diferente") -> OK | X19: =IF(W19="Diferente",F19-SUM(M19:U19),"")
B20: MARIA DANIELLY RIOS DA SILVA PAIVA | C20: 9 | D20: OK | E20: =SUM(M20:U20) -> 449.29 | F20: =E20 -> 449.29 | H20: Banco - Cora | L20: =IF(C20>=13,1,"") | M20: 328.28 | N20: 24.57 | O20: 12 | P20: 1.44 | Q20: 5 | R20: 10 | T20: 50 | U20: 18 | V20: TAXA CONFRATERNIZAÇÃO 2024 R$ 5,00; TAXA DE PREPARO 1/2 R$ 13,00 | W20: =IF(F20=SUM(M20:U20),"OK","Diferente") -> OK | X20: =IF(W20="Diferente",F20-SUM(M20:U20),"")
B21: RÉGIS BEZERRA GOMES | C21: 11 | D21: OK | E21: =SUM(M21:U21) -> 266.99 | F21: =E21 -> 266.99 | H21: Banco - Cora | L21: =IF(C21>=13,1,"") | M21: 120.98 | N21: 24.57 | O21: 12 | P21: 1.44 | Q21: 5 | R21: 5 | T21: 30 | U21: 68 | V21: COMPRA DE ARCONDICIONADO 7/10 R$ 50,00; TAXA CONFRATERNIZAÇÃO 2024 R$ 5,00; TAXA DE PREPARO 1/2 R$ 13,00 | W21: =IF(F21=SUM(M21:U21),"OK","Diferente") -> OK | X21: =IF(W21="Diferente",F21-SUM(M21:U21),"")
B22: ANA CAROLINA DE OLIVEIRA MARTINS GOMES | C22: 11 | D22: OK | E22: =SUM(M22:U22) -> 193.59 | F22: =E22 -> 193.59 | H22: Banco - Cora | L22: =IF(C22>=13,1,"") | M22: 102.58 | N22: 24.57 | O22: 12 | P22: 1.44 | Q22: 5 | T22: 30 | U22: 18 | V22: TAXA CONFRATERNIZAÇÃO 2024 R$ 5,00; TAXA DE PREPARO 1/2 R$ 13,00 | W22: =IF(F22=SUM(M22:U22),"OK","Diferente") -> OK | X22: =IF(W22="Diferente",F22-SUM(M22:U22),"")
B23: LINDAYANA DE SOUZA FLORÊNCIO | D23: Pendente | E23: =SUM(M23:U23) -> 153.34 | L23: =IF(C23>=13,1,"") | M23: 37.33 | N23: 24.57 | O23: 12 | P23: 1.44 | Q23: 5 | R23: 5 | U23: 68 | V23: COMPRA DE ARCONDICIONADO 7/10 R$ 50,00; TAXA CONFRATERNIZAÇÃO 2024 R$ 5,00; TAXA DE PREPARO 1/2 R$ 13,00 | W23: =IF(F23=SUM(M23:U23),"OK","Diferente") -> Diferente | X23: =IF(W23="Diferente",F23-SUM(M23:U23),"") -> -153.34
B24: DAVI FLORENCIO DE SOUSA | D24: Pendente | E24: =SUM(M24:U24) -> 134.44 | L24: =IF(C24>=13,1,"") | M24: 53.43 | N24: 24.57 | O24: 12 | P24: 1.44 | Q24: 5 | R24: 5 | T24: 15 | U24: 18 | V24: TAXA CONFRATERNIZAÇÃO 2024 R$ 5,00; TAXA DE PREPARO 1/2 R$ 13,00 | W24: =IF(F24=SUM(M24:U24),"OK","Diferente") -> Diferente | X24: =IF(W24="Diferente",F24-SUM(M24:U24),"") -> -134.44
B25: JOAQUIM GARCEZ DE LIMA ROCHA | D25: Pendente | E25: =SUM(M25:U25) -> 203 | L25: =IF(C25>=13,1,"") | M25: 131.99 | N25: 24.57 | O25: 12 | P25: 6.44 | R25: 10 | U25: 18 | V25: TAXA CONFRATERNIZAÇÃO 2024 R$ 5,00; TAXA DE PREPARO 1/2 R$ 13,00 | W25: =IF(F25=SUM(M25:U25),"OK","Diferente") -> Diferente | X25: =IF(W25="Diferente",F25-SUM(M25:U25),"") -> -203
B26: FRANCISCO SAULO STUDART ALBUQUERQUE | D26: Pendente | E26: =SUM(M26:U26) -> 128 | L26: =IF(C26>=13,1,"") | M26: 71.43 | N26: 24.57 | O26: 12 | P26: 2 | U26: 18 | V26: TAXA CONFRATERNIZAÇÃO 2024 R$ 5,00; TAXA DE PREPARO 1/2 R$ 13,00 | W26: =IF(F26=SUM(M26:U26),"OK","Diferente") -> Diferente | X26: =IF(W26="Diferente",F26-SUM(M26:U26),"") -> -128
B27: FRANCO COSTA E SILVA | C27: 8 | D27: OK | E27: =SUM(M27:U27) -> 598 | F27: =E27 -> 598 | H27: Banco - Cora | L27: =IF(C27>=13,1,"") | M27: 131.99 | N27: 24.57 | O27: 12 | P27: 11.44 | Q27: 5 | R27: 5 | S27: 10 | T27: 30 | U27: 368 | V27: COMPRA DE ARCONDICIONADO 7/10 R$ 50,00; TAXA AÇÃO ENTRE AMIGOS 2/2 R$ 300,00; TAXA CONFRATERNIZAÇÃO 2024 R$ 5,00; TAXA DE PREPARO 1/2 R$ 13,00 | W27: =IF(F27=SUM(M27:U27),"OK","Diferente") -> OK | X27: =IF(W27="Diferente",F27-SUM(M27:U27),"")
B28: JULIANA SOARES MONTEIRO | C28: 8 | D28: OK | E28: =SUM(M28:U28) -> 238 | F28: =E28 -> 238 | H28: Banco - Cora | L28: =IF(C28>=13,1,"") | M28: 131.99 | N28: 24.57 | O28: 12 | P28: 1.44 | Q28: 5 | R28: 5 | S28: 10 | T28: 30 | U28: 18 | V28: TAXA CONFRATERNIZAÇÃO 2024 R$ 5,00; TAXA DE PREPARO 1/2 R$ 13,00 | W28: =IF(F28=SUM(M28:U28),"OK","Diferente") -> OK | X28: =IF(W28="Diferente",F28-SUM(M28:U28),"")
B29: HUGO UCHOA PASSOS ALENCAR | C29: 13 | D29: OK | E29: =SUM(M29:U29) -> 277.69 | F29: =E29 -> 277.69 | H29: Banco - Cora | L29: =IF(C29>=13,1,"") -> 1 | M29: 116.68 | N29: 24.57 | O29: 12 | P29: 1.44 | Q29: 5 | R29: 10 | S29: 10 | T29: 30 | U29: 68 | V29: COMPRA DE ARCONDICIONADO 7/10 R$ 50,00; TAXA CONFRATERNIZAÇÃO 2024 R$ 5,00; TAXA DE PREPARO 1/2 R$ 13,00 | W29: =IF(F29=SUM(M29:U29),"OK","Diferente") -> OK | X29: =IF(W29="Diferente",F29-SUM(M29:U29),"")
B30: MAIRI ALENCAR DE LACERDA FERRAZ UCHÔA | C30: 13 | D30: OK | E30: =SUM(M30:U30) -> 176.69 | F30: =E30 -> 176.69 | H30: Banco - Cora | L30: =IF(C30>=13,1,"") -> 1 | M30: 70.68 | N30: 24.57 | O30: 12 | P30: 1.44 | R30: 10 | S30: 10 | T30: 30 | U30: 18 | V30: TAXA CONFRATERNIZAÇÃO 2024 R$ 5,00; TAXA DE PREPARO 1/2 R$ 13,00 | W30: =IF(F30=SUM(M30:U30),"OK","Diferente") -> OK | X30: =IF(W30="Diferente",F30-SUM(M30:U30),"")
B31: JOÃO CARLOS STUDART ANTERO | D31: Pendente | E31: =SUM(M31:U31) -> 185.44 | L31: =IF(C31>=13,1,"") | M31: 104.43 | N31: 24.57 | O31: 12 | P31: 1.44 | Q31: 5 | S31: 10 | T31: 10 | U31: 18 | V31: TAXA CONFRATERNIZAÇÃO 2024 R$ 5,00; TAXA DE PREPARO 1/2 R$ 13,00 | W31: =IF(F31=SUM(M31:U31),"OK","Diferente") -> Diferente | X31: =IF(W31="Diferente",F31-SUM(M31:U31),"") -> -185.44
B32: JANAÍNA SILVA LEITÃO STUDART ANTERO | D32: Pendente | E32: =SUM(M32:U32) -> 185.44 | L32: =IF(C32>=13,1,"") | M32: 104.43 | N32: 24.57 | O32: 12 | P32: 1.44 | Q32: 5 | S32: 10 | T32: 10 | U32: 18 | V32: TAXA CONFRATERNIZAÇÃO 2024 R$ 5,00; TAXA DE PREPARO 1/2 R$ 13,00 | W32: =IF(F32=SUM(M32:U32),"OK","Diferente") -> Diferente | X32: =IF(W32="Diferente",F32-SUM(M32:U32),"") -> -185.44
B33: JANAINA DE PÁDUA CARNEIRO VASCONCELOS GIFFONI | C33: 10 | D33: OK | E33: =SUM(M33:U33) -> 217.01 | F33: =E33 -> 217.01 | H33: Banco - Cora | L33: =IF(C33>=13,1,"") | M33: 156 | N33: 24.57 | O33: 12 | P33: 1.44 | Q33: 5 | U33: 18 | V33: TAXA CONFRATERNIZAÇÃO 2024 R$ 5,00; TAXA DE PREPARO 1/2 R$ 13,00 | W33: =IF(F33=SUM(M33:U33),"OK","Diferente") -> OK | X33: =IF(W33="Diferente",F33-SUM(M33:U33),"")
B34: VICENTE ALVES GIFFONI | C34: 10 | D34: OK | E34: =SUM(M34:U34) -> 287.01 | F34: =E34 -> 287.01 | H34: Banco - Cora | L34: =IF(C34>=13,1,"") | M34: 156 | N34: 24.57 | O34: 12 | P34: 11.44 | Q34: 5 | R34: 10 | U34: 68 | V34: COMPRA DE ARCONDICIONADO 7/10 R$ 50,00; TAXA CONFRATERNIZAÇÃO 2024 R$ 5,00; TAXA DE PREPARO 1/2 R$ 13,00 | W34: =IF(F34=SUM(M34:U34),"OK","Diferente") -> OK | X34: =IF(W34="Diferente",F34-SUM(M34:U34),"")
B35: RAPHAEL BRUNO DANTAS MOREIRA | D35: Pendente | E35: =SUM(M35:U35) -> 198.2 | L35: =IF(C35>=13,1,"") | M35: 131.63 | N35: 24.57 | O35: 12 | P35: 10 | Q35: 5 | R35: 15 | V35: TAXA CONFRATERNIZAÇÃO 2024 R$ 5,00; TAXA DE PREPARO 1/2 R$ 13,00 | W35: =IF(F35=SUM(M35:U35),"OK","Diferente") -> Diferente | X35: =IF(W35="Diferente",F35-SUM(M35:U35),"") -> -198.2
B36: DAVI SILVINO MORAES | C36: 9 | D36: OK | E36: =SUM(M36:U36) -> 246.76 | F36: =E36 -> 246.76 | H36: Banco - Cora | L36: =IF(C36>=13,1,"") | M36: 132.19 | N36: 24.57 | O36: 12 | P36: 5 | Q36: 5 | R36: 10 | S36: 10 | T36: 30 | U36: 18 | V36: TAXA CONFRATERNIZAÇÃO 2024 R$ 5,00; TAXA DE PREPARO 1/2 R$ 13,00 | W36: =IF(F36=SUM(M36:U36),"OK","Diferente") -> OK | X36: =IF(W36="Diferente",F36-SUM(M36:U36),"")
B37: DIMARANJE JOSÉ MORAES | D37: Pendente | E37: =SUM(M37:U37) -> 130.81 | L37: =IF(C37>=13,1,"") | M37: 74.74 | N37: 24.57 | O37: 12 | P37: 1.5 | U37: 18 | V37: TAXA CONFRATERNIZAÇÃO 2024 R$ 5,00; TAXA DE PREPARO 1/2 R$ 13,00 | W37: =IF(F37=SUM(M37:U37),"OK","Diferente") -> Diferente | X37: =IF(W37="Diferente",F37-SUM(M37:U37),"") -> -130.81
B38: SILVANE DA SILVA GONÇALVES | D38: Pendente | E38: =SUM(M38:U38) -> 130.81 | L38: =IF(C38>=13,1,"") | M38: 74.74 | N38: 24.57 | O38: 12 | P38: 1.5 | U38: 18 | V38: TAXA CONFRATERNIZAÇÃO 2024 R$ 5,00; TAXA DE PREPARO 1/2 R$ 13,00 | W38: =IF(F38=SUM(M38:U38),"OK","Diferente") -> Diferente | X38: =IF(W38="Diferente",F38-SUM(M38:U38),"") -> -130.81
B39: VICENTE DE PAULA GIFFONI FILHO | C39: 9 | D39: OK | E39: =SUM(M39:U39) -> 164.44 | F39: =E39 -> 164.44 | H39: Banco - Cora | L39: =IF(C39>=13,1,"") | M39: 103.43 | N39: 24.57 | O39: 12 | P39: 1.44 | R39: 5 | U39: 18 | V39: TAXA CONFRATERNIZAÇÃO 2024 R$ 5,00; TAXA DE PREPARO 1/2 R$ 13,00 | W39: =IF(F39=SUM(M39:U39),"OK","Diferente") -> OK | X39: =IF(W39="Diferente",F39-SUM(M39:U39),"")
B40: FRANCINETE ALVES DE OLIVEIRA GIFFONI | C40: 9 | D40: OK | E40: =SUM(M40:U40) -> 169.44 | F40: =E40 -> 169.44 | H40: Banco - Cora | L40: =IF(C40>=13,1,"") | M40: 103.43 | N40: 24.57 | O40: 12 | P40: 1.44 | Q40: 5 | R40: 5 | U40: 18 | V40: TAXA CONFRATERNIZAÇÃO 2024 R$ 5,00; TAXA DE PREPARO 1/2 R$ 13,00 | W40: =IF(F40=SUM(M40:U40),"OK","Diferente") -> OK | X40: =IF(W40="Diferente",F40-SUM(M40:U40),"")
B41: EMANUEL ALVES GIFFONI | C41: 9 | D41: OK | E41: =SUM(M41:U41) -> 169.44 | F41: =E41 -> 169.44 | H41: Banco - Cora | L41: =IF(C41>=13,1,"") | M41: 103.43 | N41: 24.57 | O41: 12 | P41: 1.44 | Q41: 5 | R41: 5 | U41: 18 | V41: TAXA CONFRATERNIZAÇÃO 2024 R$ 5,00; TAXA DE PREPARO 1/2 R$ 13,00 | W41: =IF(F41=SUM(M41:U41),"OK","Diferente") -> OK | X41: =IF(W41="Diferente",F41-SUM(M41:U41),"")
B42: FLORA ALVES GIFFONI | C42: 9 | D42: OK | E42: =SUM(M42:U42) -> 87.59 | F42: =E42 -> 87.59 | H42: Banco - Cora | L42: =IF(C42>=13,1,"") | M42: 31.58 | N42: 24.57 | O42: 12 | P42: 1.44 | U42: 18 | V42: TAXA CONFRATERNIZAÇÃO 2024 R$ 5,00; TAXA DE PREPARO 1/2 R$ 13,00 | W42: =IF(F42=SUM(M42:U42),"OK","Diferente") -> OK | X42: =IF(W42="Diferente",F42-SUM(M42:U42),"")
...

Sheet JAN-Despesas
B2: DESPESAS
B4: TOTAL | C4: - | D4: - | E4: =SUBTOTAL(9,E16,E63,E38,E135,E160,E166,E93,E6,E34,E222,E271,E172,E182,E192,E202,E212,E108) -> 0 | F4: =SUBTOTAL(9,F16,F63,F38,F125,F135,F160,F166,F93,F6,F34,F222,F271,F172,F182,F192,F202,F212,F108) -> 57344.6 | G4: - | H4: CAIXA | I4: COMPROVANTE | J4: PLANO DE CONTAS DG
C5: Data | D5: Efetivado | E5: Valor Previsto | F5: Valor Pago | G5: Observação
B6: NCL - Funcionários | C6: - | D6: - | E6: =SUM(E7:E15) -> 0 | F6: =SUMIF(D7:D15,"OK",F7:F15) -> 2182.87
B7: Salário | C7: 1 | D7: OK | E7: 0 | F7: 709.82 | G7: Pagamento realizado em duplicidade considerando que já havia sido pago em 28/12/2024. Solicitada a devolução do pix ao Wesley que informou que já havia gasto o dinheiro. O valor de R$ 709,82 será descontado no pagamento dos salários de fevereiro e março. | H7: Banco - Cora | I7: https://drive.google.com/open?id=1mdcGvPCJ-b56kQcTTnv0NHR9lz6bhKaS&usp=drive_fs
B8: 13° salário | E8: 0 | F8: 0
B9: Férias | C9: 3 | D9: OK | E9: 0 | F9: 1026.95 | G9: 20 dias de férias + 10 dias comprados pelo núcleo. | H9: Banco - Cora | I9: https://drive.google.com/open?id=1yfj64PilsAhg2ps6P13cPj6FSWgIed3F&usp=drive_fs
B10: Encargos sociais | C10: 15 | D10: OK | E10: 0 | F10: 286.14 | H10: Banco - Cora | I10: https://drive.google.com/open?id=1gRnlDb8DmOVHUU_-CiM9efxoSRDOjTjU&usp=drive_fs
B11: Encargos sociais | C11: 15 | D11: OK | E11: 0 | F11: 40.12 | H11: Banco - Cora | I11: https://drive.google.com/open?id=1gVthgjd-xQLy4bzTITepW9-LSo7JZLV9&usp=drive_fs
B12: Encargos sociais | C12: 15 | D12: OK | E12: 0 | F12: 64.85 | H12: Banco - Cora | I12: https://drive.google.com/open?id=1gNhVwxUFoN7ZOYPVqARL9Bb276j9U7PY&usp=drive_fs
B13: Encargos sociais | E13: 0 | F13: 0
B14: Cesta básica | C14: 6 | D14: OK | E14: 0 | F14: 54.99 | H14: Banco - Cora | I14: https://drive.google.com/open?id=1IfoI9Iif_r_WmewDu7PzFevppvyzTPGY&usp=drive_fs
B15: Outras despesas | E15: 0 | F15: 0
B16: NCL - Repasses | C16: - | D16: - | E16: =SUM(E17:E33) -> 0 | F16: =SUMIF(D17:D33,"OK",F17:F33) -> 7731.61
B17: Diretoria Geral - FP | C17: 29 | D17: OK | E17: 0 | F17: 1409.24 | H17: Banco - Cora | I17: https://drive.google.com/open?id=1qyuapgNjKzGYut8sjI4isL4ao-Dil0W5&usp=drive_fs
B18: Diretoria Geral - FS | C18: 29 | D18: OK | E18: 0 | F18: 802.62 | H18: Banco - Cora
B19: Diretoria Geral - FA | C19: 29 | D19: OK | E19: 0 | F19: 98 | H19: Banco - Cora
B20: Diretoria Geral - FB | C20: 29 | D20: OK | E20: 0 | F20: 98 | H20: Banco - Cora
B21: Diretoria Geral - SUC | C21: 29 | D21: OK | E21: 0 | F21: 384 | H21: Banco - Cora
B22: 11a Região - Fundo Regional | C22: 20 | D22: OK | E22: 0 | F22: =(310.65/95)*98 -> 320.46 | G22: Pagamento único de R$ 1.176,00 | H22: Banco - Cora | I22: https://drive.google.com/open?id=1me6oMu0QuwSOf0672D1h16itpT7CXm8W&usp=drive_fs
B23: 11a Região - Plantio | C23: 20 | D23: OK | E23: 0 | F23: =(356.25/95)*98 -> 367.5 | H23: Banco - Cora
B24: 11a Região - Fundo de Beneficência | C24: 20 | D24: OK | E24: 0 | F24: =(441.75/95)*98 -> 455.7 | H24: Banco - Cora
B25: 11a Região - Fundo de Reserva | C25: 20 | D25: OK | E25: 0 | F25: =(31.35/95)*98 -> 32.34 | H25: Banco - Cora
B26: 11a Região - Servidor Vreal | E26: 0 | F26: 0
B27: 11a Região - Sala da Região | E27: 0 | F27: 0
B28: 11a Região - Extra | E28: 0 | F28: 0
B29: Novo Encanto | C29: 15 | D29: OK | E29: 0 | F29: 117 | H29: Banco - Cora | I29: https://drive.google.com/open?id=1fneKxS8fcSCEk6941q_y4bYQB-3y2aNp&usp=drive_fs
B30: Flor Divina | C30: 3 | D30: OK | E30: 0 | F30: =2343.27-80 -> 2263.27 | G30: Repasse de dezembro: R$ 2.343,27 realizada em 03/01, sendo R$ 80 referente a lanche do Plantio. | H30: Banco - Cora | I30: https://drive.google.com/open?id=1XlVADbZtcXWzEBTIqPWShhKUtzx-AXoK&usp=drive_fs
B31: Memorial José Gabriel da Costa | E31: 0 | F31: 0
B32: Flor Divina | C32: 31 | D32: OK | E32: 0 | F32: 1383.48 | G32: Repasse de janeiro: R$ 1.463,48, sendo R$ 1.383,48 pago pela tesouraria e R$ 80 pelo plantio. | H32: Banco - Cora | I32: https://drive.google.com/open?id=1yEGIa44JRzSyB9hsDq2v5wHpRZ_ExjoJ&usp=drive_fs
B33: Outro repasse | E33: 0 | F33: 0
B34: NCL - Tarifas bancárias | C34: - | D34: - | E34: =SUM(E35:E37) -> 0 | F34: =SUMIF(D35:D37,"OK",F35:F37) -> 1.89
B35: IR Rendimento Pagbank | C35: 2 | D35: OK | E35: 0 | F35: 1.89 | H35: Banco - Pagbank | I35: https://drive.google.com/open?id=1jHVfJCXu0-ZoBNffO1AqvlkvOq2K4JJP&usp=drive_fs
B36: Encerramento conta itaú | E36: 0 | F36: 0
B37: Tarifa 3 | E37: 0 | F37: 0
B38: NCL - Despesas gerais | C38: - | D38: - | E38: =SUM(E39:E62) -> 0 | F38: =SUMIF(D39:D62,"OK",F39:F62) -> 4886.5
B39: Energia Elétrica | C39: 31 | D39: OK | E39: 0 | F39: 795.7 | H39: Banco - Cora | I39: https://drive.google.com/open?id=1ma8w6Q6gU7pvYjO6f4zoUEVNUEMJ0uEg&usp=drive_fs
B40: Vigilância - 1a escala | C40: 5 | D40: OK | E40: 0 | F40: 650 | H40: Banco - Cora | I40: https://drive.google.com/open?id=1nYs5-oiWryI6gqMDbVz2yIXNsS9wlpfW&usp=drive_fs
B41: Vigilância - 2a escala | C41: 19 | D41: OK | E41: 0 | F41: 650 | H41: Banco - Cora | I41: https://drive.google.com/open?id=1TFH-yvYsU0O4H-HXjX5jxifCZ1CRuV5i&usp=drive_fs
B42: Contabilidade | E42: 0 | F42: 0
...

Sheet FEV-Receitas
B2: RECEITAS
B4: TOTAL | E4: =SUM(E6,E127,E147,E169,E173) -> 16476.43 | F4: =SUM(F6,F127,F147,F169,F173) -> 22658.55 | H4: CAIXA | I4: PLANO DE CONTAS DG
C5: Data | D5: Efetivado | E5: Valor Previsto | F5: Valor Recebido | G5: Observação | J5: Inadimp. (qtd) | K5: Inadimp. (R$) | L5: % Atraso | M5: Núcleo | N5: Repasse DG | O5: Repasse 11a R | P5: Benef. NLT | Q5: NE NLT | R5: Plantio NLT | S5: FR Bilhete Aéreo | T5: FR Construção | U5: Taxa Extra | V5: Detalhamento Taxa Extra | X5: A receber:
B6: Mensalidade | C6: 10 | D6: - | E6: =SUM(E7:E126) -> 16476.43 | F6: =SUMIF(D7:D126,"OK",F7:F126)+SUMIF(D7:D126,"Parcial",F7:F126) -> 15875.15 | G6: - | J6: =(COUNTIF(D7:D126,"Pendente")+COUNTIF(D7:D126,"Parcial"))/COUNTA(B7:B126) -> 0.0625 | K6: =IFERROR(-(X6/E6),"Pendente info") -> 0.14081813 | L6: =SUM(L7:L105)/COUNTA(B7:B105) -> 0.11458333 | M6: =SUMIF($D$7:$D$126,"OK",M7:M126)+SUMIF($D$7:$D$126,"Parcial",M7:M126) -> 8734.3 | N6: =SUMIF($D$7:$D$126,"OK",N7:N126)+SUMIF($D$7:$D$126,"Parcial",N7:N126) -> 2137.59 | O6: =SUMIF($D$7:$D$126,"OK",O7:O126)+SUMIF($D$7:$D$126,"Parcial",O7:O126) -> 1044 | P6: =SUMIF($D$7:$D$126,"OK",P7:P126)+SUMIF($D$7:$D$126,"Parcial",P7:P126) -> 223.26 | Q6: =SUMIF($D$7:$D$126,"OK",Q7:Q126)+SUMIF($D$7:$D$126,"Parcial",Q7:Q126) -> 215 | R6: =SUMIF($D$7:$D$126,"OK",R7:R126)+SUMIF($D$7:$D$126,"Parcial",R7:R126) -> 260 | S6: =SUMIF($D$7:$D$126,"OK",S7:S126)+SUMIF($D$7:$D$126,"Parcial",S7:S126) -> 297 | T6: =SUMIF($D$7:$D$126,"OK",T7:T126)+SUMIF($D$7:$D$126,"Parcial",T7:T126) -> 610 | U6: =SUMIF($D$7:$D$126,"OK",U7:U126)+SUMIF($D$7:$D$126,"Parcial",U7:U126) -> 2354 | V6: - | W6: =IF(F6=SUM(M6:U6),"OK","Diferente") -> OK | X6: =SUM(X7:X126) -> -2320.18
B7: ELPÍDIO GOMES DE MOURA NETO | D7: OK | E7: 0 | L7: =IF(C7>=13,1,"") | W7: =IF(F7=SUM(M7:U7),"OK","Diferente") -> OK | X7: =IF(W7="Diferente",F7-SUM(M7:U7),"")
B8: JULIANA COLLYER ARRUDA DE MOURA | D8: OK | E8: 0 | L8: =IF(C8>=13,1,"") | W8: =IF(F8=SUM(M8:U8),"OK","Diferente") -> OK | X8: =IF(W8="Diferente",F8-SUM(M8:U8),"")
B9: SILVERIA LOPES VASCONCELOS ARRUDA | D9: OK | E9: 0 | L9: =IF(C9>=13,1,"") | W9: =IF(F9=SUM(M9:U9),"OK","Diferente") -> OK | X9: =IF(W9="Diferente",F9-SUM(M9:U9),"")
B10: FRANCISCO DE ASSIS VASCONCELOS ARRUDA | D10: OK | E10: 0 | L10: =IF(C10>=13,1,"") | W10: =IF(F10=SUM(M10:U10),"OK","Diferente") -> OK | X10: =IF(W10="Diferente",F10-SUM(M10:U10),"")
B11: ANTÔNIO GONÇALVES DE LIMA FILHO | C11: 7 | D11: OK | E11: =SUM(M11:U11) -> 188.43 | F11: =E11 -> 188.43 | H11: Banco - Cora | L11: =IF(C11>=13,1,"") | M11: 130 | N11: 24.57 | O11: 12 | P11: 3.86 | Q11: 5 | U11: 13 | V11: TAXA DE PREPARO 2/2 R$ 13,00 | W11: =IF(F11=SUM(M11:U11),"OK","Diferente") -> OK | X11: =IF(W11="Diferente",F11-SUM(M11:U11),"")
B12: SANDRA BORGES GONÇALVES DE LIMA | C12: 7 | D12: OK | E12: =SUM(M12:U12) -> 181.57 | F12: =E12 -> 181.57 | H12: Banco - Cora | L12: =IF(C12>=13,1,"") | M12: 130 | N12: 24.57 | O12: 12 | P12: 2 | U12: 13 | V12: TAXA DE PREPARO 2/2 R$ 13,00 | W12: =IF(F12=SUM(M12:U12),"OK","Diferente") -> OK | X12: =IF(W12="Diferente",F12-SUM(M12:U12),"")
B13: MARCELO DE CASTRO BRASIL | E13: =SUM(M13:U13) -> 361.49 | L13: =IF(C13>=13,1,"") | M13: 130.48 | N13: 24.57 | O13: 12 | P13: 1.44 | Q13: 10 | R13: 20 | S13: 50 | T13: 50 | U13: 63 | V13: COMPRA DE ARCONDICIONADO 8/10 R$ 50,00; TAXA DE PREPARO 2/2 R$ 13,00 | W13: =IF(F13=SUM(M13:U13),"OK","Diferente") -> Diferente | X13: =IF(W13="Diferente",F13-SUM(M13:U13),"") -> -361.49
B14: FLORA BORGES GONÇALVES LIMA BRASIL | E14: =SUM(M14:U14) -> 204.29 | L14: =IF(C14>=13,1,"") | M14: 98.28 | N14: 24.57 | O14: 12 | P14: 1.44 | Q14: 5 | T14: 50 | U14: 13 | V14: TAXA DE PREPARO 2/2 R$ 13,00 | W14: =IF(F14=SUM(M14:U14),"OK","Diferente") -> Diferente | X14: =IF(W14="Diferente",F14-SUM(M14:U14),"") -> -204.29
B15: CÁSSIO PEREIRA COSTA SOUSA | C15: 1 | D15: Parcial | E15: 311.14 | F15: =SUM(M15:U15) -> 311.14 | G15: Este valor está lançado, porém não houve transação bancária. A C. Mônica solicitou que 4 compras da Organ realizadas por ela fossem abatidas do valor da mensalidade de janeiro. As 4 compras totalizam R$ 449,41, enquanto o valor da mensalidade é R$ 472,13. Dessa forma, foi lançado o valor de R$ 449,41 como receita de mensalidade para equiparar esta despesa. Resta ainda R$ 22,72 da mensalidade de janeiro e R$ 462,13 da mensalidade de fevereiro. | H15: Banco - Cora | L15: =IF(C15>=13,1,"") | M15: 180.13 | N15: 24.57 | O15: 12 | P15: 1.44 | Q15: 5 | R15: 5 | S15: 20 | U15: 63 | V15: COMPRA DE ARCONDICIONADO 8/10 R$ 50,00; TAXA DE PREPARO 2/2 R$ 13,00 | W15: =IF(F15=SUM(M15:U15),"OK","Diferente") -> OK | X15: =IF(W15="Diferente",F15-SUM(M15:U15),"")
B16: MÔNICA DE ARAUJO CAMPOS COSTA SOUSA | C16: 1 | D16: Parcial | E16: 150.99 | F16: =SUM(M16:U16) -> 138.27 | H16: Banco - Cora | L16: =IF(C16>=13,1,"") | M16: =89.98-22.72+10 -> 77.26 | N16: 24.57 | O16: 12 | P16: 1.44 | Q16: 5 | R16: 5 | U16: 13 | V16: TAXA DE PREPARO 2/2 R$ 13,00 | W16: =IF(F16=SUM(M16:U16),"OK","Diferente") -> OK | X16: =IF(W16="Diferente",F16-SUM(M16:U16),"")
B17: JOSÉ MAURÍCIO GUIMARÃES GOMES | C17: 4 | D17: OK | E17: =SUM(M17:U17) -> 247.19 | F17: =E17 -> 247.19 | H17: Banco - Cora | L17: =IF(C17>=13,1,"") | M17: 191.18 | N17: 24.57 | O17: 12 | P17: 1.44 | Q17: 5 | U17: 13 | V17: TAXA DE PREPARO 2/2 R$ 13,00 | W17: =IF(F17=SUM(M17:U17),"OK","Diferente") -> OK | X17: =IF(W17="Diferente",F17-SUM(M17:U17),"")
B18: TICIANE ARAGAO DA SILVEIRA GOMES | C18: 4 | D18: OK | E18: =SUM(M18:U18) -> 186.99 | F18: =E18 -> 186.99 | H18: Banco - Cora | L18: =IF(C18>=13,1,"") | M18: 135.98 | N18: 24.57 | O18: 12 | P18: 1.44 | U18: 13 | V18: TAXA DE PREPARO 2/2 R$ 13,00 | W18: =IF(F18=SUM(M18:U18),"OK","Diferente") -> OK | X18: =IF(W18="Diferente",F18-SUM(M18:U18),"")
B19: SERVULO SIDNEY GLADIUS PAIVA PIMENTEL | C19: 4 | D19: OK | E19: =SUM(M19:U19) -> 454.29 | F19: =E19 -> 454.29 | H19: Banco - Cora | L19: =IF(C19>=13,1,"") | M19: 328.28 | N19: 24.57 | O19: 12 | P19: 11.44 | Q19: 5 | R19: 10 | T19: 50 | U19: 13 | V19: TAXA DE PREPARO 2/2 R$ 13,00 | W19: =IF(F19=SUM(M19:U19),"OK","Diferente") -> OK | X19: =IF(W19="Diferente",F19-SUM(M19:U19),"")
B20: MARIA DANIELLY RIOS DA SILVA PAIVA | C20: 4 | D20: OK | E20: =SUM(M20:U20) -> 444.29 | F20: =E20 -> 444.29 | H20: Banco - Cora | L20: =IF(C20>=13,1,"") | M20: 328.28 | N20: 24.57 | O20: 12 | P20: 1.44 | Q20: 5 | R20: 10 | T20: 50 | U20: 13 | V20: TAXA DE PREPARO 2/2 R$ 13,00 | W20: =IF(F20=SUM(M20:U20),"OK","Diferente") -> OK | X20: =IF(W20="Diferente",F20-SUM(M20:U20),"")
B21: RÉGIS BEZERRA GOMES | C21: 14 | D21: OK | E21: =SUM(M21:U21) -> 261.99 | F21: =E21 -> 261.99 | H21: Banco - Cora | L21: =IF(C21>=13,1,"") -> 1 | M21: 120.98 | N21: 24.57 | O21: 12 | P21: 1.44 | Q21: 5 | R21: 5 | T21: 30 | U21: 63 | V21: COMPRA DE ARCONDICIONADO 8/10 R$ 50,00; TAXA DE PREPARO 2/2 R$ 13,00 | W21: =IF(F21=SUM(M21:U21),"OK","Diferente") -> OK | X21: =IF(W21="Diferente",F21-SUM(M21:U21),"")
B22: ANA CAROLINA DE OLIVEIRA MARTINS GOMES | C22: 14 | D22: OK | E22: =SUM(M22:U22) -> 188.59 | F22: =E22 -> 188.59 | H22: Banco - Cora | L22: =IF(C22>=13,1,"") -> 1 | M22: 102.58 | N22: 24.57 | O22: 12 | P22: 1.44 | Q22: 5 | T22: 30 | U22: 13 | V22: TAXA DE PREPARO 2/2 R$ 13,00 | W22: =IF(F22=SUM(M22:U22),"OK","Diferente") -> OK | X22: =IF(W22="Diferente",F22-SUM(M22:U22),"")
B23: LINDAYANA DE SOUZA FLORÊNCIO | E23: =SUM(M23:U23) -> 148.34 | L23: =IF(C23>=13,1,"") | M23: 37.33 | N23: 24.57 | O23: 12 | P23: 1.44 | Q23: 5 | R23: 5 | U23: 63 | V23: COMPRA DE ARCONDICIONADO 8/10 R$ 50,00; TAXA DE PREPARO 2/2 R$ 13,00 | W23: =IF(F23=SUM(M23:U23),"OK","Diferente") -> Diferente | X23: =IF(W23="Diferente",F23-SUM(M23:U23),"") -> -148.34
B24: DAVI FLORENCIO DE SOUSA | E24: =SUM(M24:U24) -> 129.44 | L24: =IF(C24>=13,1,"") | M24: 53.43 | N24: 24.57 | O24: 12 | P24: 1.44 | Q24: 5 | R24: 5 | T24: 15 | U24: 13 | V24: TAXA DE PREPARO 2/2 R$ 13,00 | W24: =IF(F24=SUM(M24:U24),"OK","Diferente") -> Diferente | X24: =IF(W24="Diferente",F24-SUM(M24:U24),"") -> -129.44
B25: JOAQUIM GARCEZ DE LIMA ROCHA | C25: 7 | D25: OK | E25: =SUM(M25:U25) -> 198 | F25: =E25 -> 198 | H25: Banco - Cora | L25: =IF(C25>=13,1,"") | M25: 131.99 | N25: 24.57 | O25: 12 | P25: 6.44 | R25: 10 | U25: 13 | V25: TAXA DE PREPARO 2/2 R$ 13,00 | W25: =IF(F25=SUM(M25:U25),"OK","Diferente") -> OK | X25: =IF(W25="Diferente",F25-SUM(M25:U25),"")
B26: FRANCISCO SAULO STUDART ALBUQUERQUE | E26: =SUM(M26:U26) -> 123 | L26: =IF(C26>=13,1,"") | M26: 71.43 | N26: 24.57 | O26: 12 | P26: 2 | U26: 13 | V26: TAXA DE PREPARO 2/2 R$ 13,00 | W26: =IF(F26=SUM(M26:U26),"OK","Diferente") -> Diferente | X26: =IF(W26="Diferente",F26-SUM(M26:U26),"") -> -123
B27: FRANCO COSTA E SILVA | C27: 11 | D27: OK | E27: =SUM(M27:U27) -> 393 | F27: =E27 -> 393 | H27: Banco - Cora | L27: =IF(C27>=13,1,"") | M27: 131.99 | N27: 24.57 | O27: 12 | P27: 11.44 | Q27: 5 | R27: 5 | S27: 10 | T27: 30 | U27: 163 | V27: COMPRA DE ARCONDICIONADO 8/10 R$ 50,00; TAXA DE PREPARO 2/2 R$ 13,00; DOAÇÃO CANTINA SANA R$ 100,00 | W27: =IF(F27=SUM(M27:U27),"OK","Diferente") -> OK | X27: =IF(W27="Diferente",F27-SUM(M27:U27),"")
B28: JULIANA SOARES MONTEIRO | C28: 11 | D28: OK | E28: =SUM(M28:U28) -> 233 | F28: =E28 -> 233 | H28: Banco - Cora | L28: =IF(C28>=13,1,"") | M28: 131.99 | N28: 24.57 | O28: 12 | P28: 1.44 | Q28: 5 | R28: 5 | S28: 10 | T28: 30 | U28: 13 | V28: TAXA DE PREPARO 2/2 R$ 13,00 | W28: =IF(F28=SUM(M28:U28),"OK","Diferente") -> OK | X28: =IF(W28="Diferente",F28-SUM(M28:U28),"")
B29: HUGO UCHOA PASSOS ALENCAR | C29: 11 | D29: OK | E29: =SUM(M29:U29) -> 272.69 | F29: =E29 -> 272.69 | H29: Banco - Cora | L29: =IF(C29>=13,1,"") | M29: 116.68 | N29: 24.57 | O29: 12 | P29: 1.44 | Q29: 5 | R29: 10 | S29: 10 | T29: 30 | U29: 63 | V29: COMPRA DE ARCONDICIONADO 8/10 R$ 50,00; TAXA DE PREPARO 2/2 R$ 13,00 | W29: =IF(F29=SUM(M29:U29),"OK","Diferente") -> OK | X29: =IF(W29="Diferente",F29-SUM(M29:U29),"")
B30: MAIRI ALENCAR DE LACERDA FERRAZ UCHÔA | C30: 11 | D30: OK | E30: =SUM(M30:U30) -> 171.69 | F30: =E30 -> 171.69 | H30: Banco - Cora | L30: =IF(C30>=13,1,"") | M30: 70.68 | N30: 24.57 | O30: 12 | P30: 1.44 | R30: 10 | S30: 10 | T30: 30 | U30: 13 | V30: TAXA DE PREPARO 2/2 R$ 13,00 | W30: =IF(F30=SUM(M30:U30),"OK","Diferente") -> OK | X30: =IF(W30="Diferente",F30-SUM(M30:U30),"")
B31: JOÃO CARLOS STUDART ANTERO | C31: 4 | D31: Parcial | E31: 180.44 | F31: =SUM(M31:U31) -> 350.88 | G31: Realizado o pagamento das mensalidades de dezembro e janeiro. Permane pendente fevereiro. | H31: Banco - Cora | L31: =IF(C31>=13,1,"") | M31: =104.43*2 -> 208.86 | N31: =24.57*2 -> 49.14 | O31: =12*2 -> 24 | P31: =1.44*2 -> 2.88 | Q31: =5*2 -> 10 | S31: =10*2 -> 20 | T31: =10*2 -> 20 | U31: 16 | V31: TAXA DE PREPARO 2/2 R$ 13,00 | W31: =IF(F31=SUM(M31:U31),"OK","Diferente") -> OK | X31: =IF(W31="Diferente",F31-SUM(M31:U31),"")
B32: JANAÍNA SILVA LEITÃO STUDART ANTERO | C32: 4 | D32: Parcial | E32: 180.44 | F32: =SUM(M32:U32) -> 334.88 | H32: Banco - Cora | L32: =IF(C32>=13,1,"") | M32: =104.43*2 -> 208.86 | N32: =24.57*2 -> 49.14 | O32: =12*2 -> 24 | P32: =1.44*2 -> 2.88 | Q32: =5*2 -> 10 | S32: =10*2 -> 20 | T32: =10*2 -> 20 | V32: TAXA DE PREPARO 2/2 R$ 13,00 | W32: =IF(F32=SUM(M32:U32),"OK","Diferente") -> OK | X32: =IF(W32="Diferente",F32-SUM(M32:U32),"")
B33: JANAINA DE PÁDUA CARNEIRO VASCONCELOS GIFFONI | C33: 10 | D33: OK | E33: =SUM(M33:U33) -> 212.01 | F33: =E33 -> 212.01 | H33: Banco - Cora | L33: =IF(C33>=13,1,"") | M33: 156 | N33: 24.57 | O33: 12 | P33: 1.44 | Q33: 5 | U33: 13 | V33: TAXA DE PREPARO 2/2 R$ 13,00 | W33: =IF(F33=SUM(M33:U33),"OK","Diferente") -> OK | X33: =IF(W33="Diferente",F33-SUM(M33:U33),"")
B34: VICENTE ALVES GIFFONI | C34: 10 | D34: OK | E34: =SUM(M34:U34) -> 282.01 | F34: =E34 -> 282.01 | H34: Banco - Cora | L34: =IF(C34>=13,1,"") | M34: 156 | N34: 24.57 | O34: 12 | P34: 11.44 | Q34: 5 | R34: 10 | U34: 63 | V34: COMPRA DE ARCONDICIONADO 8/10 R$ 50,00; TAXA DE PREPARO 2/2 R$ 13,00 | W34: =IF(F34=SUM(M34:U34),"OK","Diferente") -> OK | X34: =IF(W34="Diferente",F34-SUM(M34:U34),"")
B35: RAPHAEL BRUNO DANTAS MOREIRA | C35: 19 | D35: OK | E35: =211.2-13 -> 198.2 | F35: =SUM(M35:U35) -> 396.4 | H35: Banco - Cora | L35: =IF(C35>=13,1,"") -> 1 | M35: =131.63*2 -> 263.26 | N35: =24.57*2 -> 49.14 | O35: =12*2 -> 24 | P35: 20 | Q35: 10 | R35: 30 | V35: TAXA DE PREPARO 2/2 R$ 13,00 | W35: =IF(F35=SUM(M35:U35),"OK","Diferente") -> OK | X35: =IF(W35="Diferente",F35-SUM(M35:U35),"")
B36: DAVI SILVINO MORAES | C36: 5 | D36: OK | E36: =SUM(M36:U36) -> 241.76 | F36: =E36 -> 241.76 | H36: Banco - Cora | L36: =IF(C36>=13,1,"") | M36: 132.19 | N36: 24.57 | O36: 12 | P36: 5 | Q36: 5 | R36: 10 | S36: 10 | T36: 30 | U36: 13 | V36: TAXA DE PREPARO 2/2 R$ 13,00 | W36: =IF(F36=SUM(M36:U36),"OK","Diferente") -> OK | X36: =IF(W36="Diferente",F36-SUM(M36:U36),"")
B37: DIMARANJE JOSÉ MORAES | E37: =SUM(M37:U37) -> 125.81 | L37: =IF(C37>=13,1,"") | M37: 74.74 | N37: 24.57 | O37: 12 | P37: 1.5 | U37: 13 | V37: TAXA DE PREPARO 2/2 R$ 13,00 | W37: =IF(F37=SUM(M37:U37),"OK","Diferente") -> Diferente | X37: =IF(W37="Diferente",F37-SUM(M37:U37),"") -> -125.81
