Workbook

Sheet Entenda a planilha
B2: ABAIXO É EXPLICADO O QUE CONSTA EM CADA ABA DA PLANILHA:
B4: CAIXA
C5: Nesta aba é exibido o valor que consta em cada caixa do Núcleo no último dia do mês, ou seja, o valor em espécie e o valor em cada conta bancária, mês a mês.
B7: DISTRIB. VALORES
C8: Nesta aba mostra como o dinheiro do Núcleo está distribuído, mês a mês, considerando o valor operacional para uso da Tesouraria, Beneficência, Novo Encanto, Plantio, Fundo de Reserva de Bilhete Aéreo e Fundo de Reserva para Construções. É possível visualizar quanto tivemos de receita e despesa para cada linha, bem como o saldo atual.
B10: DINHEIRO
C11: Nesta aba consta a movimentação em dinheiro, mês a mês. Observação: - Quando há um depósito em dinheiro cujo valor sai do caixa em espécie e entra para uma conta bancária do núcleo, irá constar uma despesa nessa aba e uma receita na aba "TRANSF. ENTRE CONTAS". - Quando há um saque de dinheiro de alguma conta bancária do núcleo, irá constar uma receita nessa aba e uma despesa na aba "TRANSF. ENTRE CONTAS".
B13: TRANSF. ENTRE CONTAS
C14: Nesta aba consta a movimentação entre contas bancárias do núcleo, mês a mês. Observação: - Quando há um depósito em dinheiro cujo valor sai do caixa em espécie e entra para uma conta do núcleo, irá constar uma despesa nessa aba e uma receita na aba "TRANSF. ENTRE CONTAS". - Quando há um saque de dinheiro de alguma conta bancária do núcleo, irá constar uma receita nessa aba e uma despesa na aba "TRANSF. ENTRE CONTAS".
B16: ANO-MÊS-RECEITAS
C17: Nesta aba constam todas as receitas do Núcleo no referido mês, indicando a data da receita, se a receita foi efetivada ou não e em qual caixa a receita "entrou". Haverá uma aba desta para cada mês.
B19: ANO-MÊS-DESPESAS
C20: Nesta aba constam todas as despesas do Núcleo no referido mês, indicando a data da despesa, se a receita foi efetivada ou não, a partir de qual caixa a despesa foi paga e o link para acesso ao comprovante. Haverá uma aba desta para cada mês.
B22: INADIMPLÊNCIA
C23: Nesta aba consta a relação dos sócios inadimplentes no momento, bem como os respectivos valores.
B25: ANO-PREVISTO
C26: Nesta aba consta uma visão consolidada de todas as receitas e despesas previstas para o ano, mês a mês, possibilitando obter uma projeção financeira para o Núcleo ao longo do ano.
B28: ANO-REALIZADO
C29: Nesta aba consta uma visão consolidada de todas as receitas e despesas realizadas no ano, mês a mês, possibilitando obter uma visão gerencial da saúde financeira do Núcleo ao longo do ano.
B31: REUNIÃO DE DIRETORIA
C32: Nesta aba consta o material a ser apresentado na reunião de diretoria.

Sheet Caixa
B2: CAIXAS | C2: SALDO FINAL NOV/23 | D2: 2025
D3: JAN | E3: FEV | F3: MAR | G3: ABR | H3: MAI | I3: JUN | J3: JUL | K3: AGO | L3: SET | M3: OUT | N3: NOV | O3: DEZ
B4: Tesouraria | C4: =SUM(C5:C7) -> 33064.72 | D4: =SUM(D5:D8) -> 6618.93 | E4: =SUM(E5:E8) -> 6154.35 | F4: =SUM(F5:F8) -> 2892.19 | G4: =SUM(G5:G8) -> 6114.32 | H4: =SUM(H5:H8) -> 9821.9 | I4: =SUM(I5:I8) -> 27053.57 | J4: =SUM(J5:J8) -> 9510.64 | K4: =SUM(K5:K8) -> 9510.64 | ... O4: =SUM(O5:O8) -> 9510.64
B5: Dinheiro em espécie | C5: 1076.55 | D5: =2724.62+Dinheiro!D4 -> 5534.2 | E5: =D5+Dinheiro!E4 -> 1684.2 | F5: =E5+Dinheiro!F4 -> 727.2 | G5: =F5+Dinheiro!G4 -> 422.2 | H5: =G5+Dinheiro!H4 -> 534.2 | I5: =H5+Dinheiro!I4 -> 614.2 | J5: 614.2 | K5: =J5+Dinheiro!K4 -> 614.2 | L5: =K5+Dinheiro!L4 -> 614.2 | M5: =L5+Dinheiro!M4 -> 614.2 | N5: =M5+Dinheiro!N4 -> 614.2 | O5: =N5+Dinheiro!O4 -> 614.2
B6: Banco - Cora | C6: =582.43 -> 582.43 | D6: =10726.18+SUMIF('JAN-Receitas'!$H:$H,$B$6,'JAN-Receitas'!$F:$F)-SUMIF('JAN-Despesas'!$H:$H,$B$6,'JAN-Despesas'!$F:$F)-'Mov. entre Contas'!C11+'Mov. entre Contas'!C6 -> 849.26 | E6: =D6+SUMIF('FEV-Receitas'!$H:$H,$B$6,'FEV-Receitas'!$F:$F)-SUMIF('FEV-Despesas'!$H:$H,$B$6,'FEV-Despesas'!$F:$F)-'Mov. entre Contas'!D11+'Mov. entre Contas'!D6 -> 3970.15 | F6: =E6+SUMIF('MAR-Receitas'!$H:$H,$B$6,'MAR-Receitas'!$F:$F)-SUMIF('MAR-Despesas'!$H:$H,$B$6,'MAR-Despesas'!$F:$F)-'Mov. entre Contas'!E11+'Mov. entre Contas'!E6 -> 186.57 | G6: =F6+SUMIF('ABR-Receitas'!$H:$H,$B$6,'ABR-Receitas'!$F:$F)-SUMIF('ABR-Despesas'!$H:$H,$B$6,'ABR-Despesas'!$F:$F)-'Mov. entre Contas'!F11+'Mov. entre Contas'!F6 -> 3875.76 | H6: =G6+SUMIF('MAI-Receitas'!$H:$H,$B$6,'MAI-Receitas'!$F:$F)-SUMIF('MAI-Despesas'!$H:$H,$B$6,'MAI-Despesas'!$F:$F)-'Mov. entre Contas'!G11+'Mov. entre Contas'!G6 -> 5906.89 | I6: =H6+SUMIF('JUN-Receitas'!$H:$H,$B$6,'JUN-Receitas'!$F:$F)-SUMIF('JUN-Despesas'!$H:$H,$B$6,'JUN-Despesas'!$F:$F)-'Mov. entre Contas'!H11+'Mov. entre Contas'!H6 -> 12222.97 | J6: 8025.67 | K6: =J6+SUMIF('AGO-Receitas'!$H:$H,$B$6,'AGO-Receitas'!$F:$F)-SUMIF('AGO-Despesas'!$H:$H,$B$6,'AGO-Despesas'!$F:$F)-'Mov. entre Contas'!J11+'Mov. entre Contas'!J6 -> 8025.67 | L6: =K6+SUMIF('SET-Receitas'!$H:$H,$B$6,'SET-Receitas'!$F:$F)-SUMIF('SET-Despesas'!$H:$H,$B$6,'SET-Despesas'!$F:$F)-'Mov. entre Contas'!K11+'Mov. entre Contas'!K6 -> 8025.67 | M6: =L6+SUMIF('OUT-Receitas'!$H:$H,$B$6,'OUT-Receitas'!$F:$F)-SUMIF('OUT-Despesas'!$H:$H,$B$6,'OUT-Despesas'!$F:$F)-'Mov. entre Contas'!L11+'Mov. entre Contas'!L6 -> 8025.67 | N6: =M6+SUMIF('NOV-Receitas'!$H:$H,$B$6,'NOV-Receitas'!$F:$F)-SUMIF('NOV-Despesas'!$H:$H,$B$6,'NOV-Despesas'!$F:$F)-'Mov. entre Contas'!M11+'Mov. entre Contas'!M6 -> 8025.67 | O6: =N6+SUMIF('DEZ-Receitas'!$H:$H,$B$6,'DEZ-Receitas'!$F:$F)-SUMIF('DEZ-Despesas'!$H:$H,$B$6,'DEZ-Despesas'!$F:$F)-'Mov. entre Contas'!N11+'Mov. entre Contas'!N6 -> 8025.67
B7: Banco - Pagbank | C7: 31405.74 | D7: =876.739999999969+SUMIF('JAN-Receitas'!$H:$H,$B$7,'JAN-Receitas'!$F:$F)-SUMIF('JAN-Despesas'!$H:$H,$B$7,'JAN-Despesas'!$F:$F)-'Mov. entre Contas'!C12+'Mov. entre Contas'!C7 -> 220.47 | E7: =D7+SUMIF('FEV-Receitas'!$H:$H,$B$7,'FEV-Receitas'!$F:$F)-SUMIF('FEV-Despesas'!$H:$H,$B$7,'FEV-Despesas'!$F:$F)-'Mov. entre Contas'!D12+'Mov. entre Contas'!D7 -> 500 | F7: =E7+SUMIF('MAR-Receitas'!$H:$H,$B$7,'MAR-Receitas'!$F:$F)-SUMIF('MAR-Despesas'!$H:$H,$B$7,'MAR-Despesas'!$F:$F)-'Mov. entre Contas'!E12+'Mov. entre Contas'!E7 -> 1005.12 | G7: =F7+SUMIF('ABR-Receitas'!$H:$H,$B$7,'ABR-Receitas'!$F:$F)-SUMIF('ABR-Despesas'!$H:$H,$B$7,'ABR-Despesas'!$F:$F)-'Mov. entre Contas'!F12+'Mov. entre Contas'!F7 -> 452.55 | H7: =G7+SUMIF('MAI-Receitas'!$H:$H,$B$7,'MAI-Receitas'!$F:$F)-SUMIF('MAI-Despesas'!$H:$H,$B$7,'MAI-Despesas'!$F:$F)-'Mov. entre Contas'!G12+'Mov. entre Contas'!G7 -> -2.9558578e-11 | I7: =H7+SUMIF('JUN-Receitas'!$H:$H,$B$7,'JUN-Receitas'!$F:$F)-SUMIF('JUN-Despesas'!$H:$H,$B$7,'JUN-Despesas'!$F:$F)-'Mov. entre Contas'!H12+'Mov. entre Contas'!H7 -> 11980.44 | J7: 712.77 | K7: =J7+SUMIF('AGO-Receitas'!$H:$H,$B$7,'AGO-Receitas'!$F:$F)-SUMIF('AGO-Despesas'!$H:$H,$B$7,'AGO-Despesas'!$F:$F)-'Mov. entre Contas'!J12+'Mov. entre Contas'!J7 -> 712.77 | L7: =K7+SUMIF('SET-Receitas'!$H:$H,$B$7,'SET-Receitas'!$F:$F)-SUMIF('SET-Despesas'!$H:$H,$B$7,'SET-Despesas'!$F:$F)-'Mov. entre Contas'!K12+'Mov. entre Contas'!K7 -> 712.77 | M7: =L7+SUMIF('OUT-Receitas'!$H:$H,$B$7,'OUT-Receitas'!$F:$F)-SUMIF('OUT-Despesas'!$H:$H,$B$7,'OUT-Despesas'!$F:$F)-'Mov. entre Contas'!L12+'Mov. entre Contas'!L7 -> 712.77 | N7: =M7+SUMIF('NOV-Receitas'!$H:$H,$B$7,'NOV-Receitas'!$F:$F)-SUMIF('NOV-Despesas'!$H:$H,$B$7,'NOV-Despesas'!$F:$F)-'Mov. entre Contas'!M12+'Mov. entre Contas'!M7 -> 712.77 | O7: =N7+SUMIF('DEZ-Receitas'!$H:$H,$B$7,'DEZ-Receitas'!$F:$F)-SUMIF('DEZ-Despesas'!$H:$H,$B$7,'DEZ-Despesas'!$F:$F)-'Mov. entre Contas'!N12+'Mov. entre Contas'!N7 -> 712.77
B8: Banco - Stone | D8: =343+SUMIF('JAN-Receitas'!$H:$H,$B$8,'JAN-Receitas'!$F:$F)-SUMIF('JAN-Despesas'!$H:$H,$B$8,'JAN-Despesas'!$F:$F)-'Mov. entre Contas'!C13+'Mov. entre Contas'!C8 -> 15 | E8: =D8+SUMIF('FEV-Receitas'!$H:$H,$B$8,'FEV-Receitas'!$F:$F)-SUMIF('FEV-Despesas'!$H:$H,$B$8,'FEV-Despesas'!$F:$F)-'Mov. entre Contas'!D13+'Mov. entre Contas'!D8 -> 0 | F8: =E8+SUMIF('MAR-Receitas'!$H:$H,$B$8,'MAR-Receitas'!$F:$F)-SUMIF('MAR-Despesas'!$H:$H,$B$8,'MAR-Despesas'!$F:$F)-'Mov. entre Contas'!E13+'Mov. entre Contas'!E8 -> 973.3 | G8: =F8+SUMIF('ABR-Receitas'!$H:$H,$B$8,'ABR-Receitas'!$F:$F)-SUMIF('ABR-Despesas'!$H:$H,$B$8,'ABR-Despesas'!$F:$F)-'Mov. entre Contas'!F13+'Mov. entre Contas'!F8 -> 1363.81 | H8: =G8+SUMIF('MAI-Receitas'!$H:$H,$B$8,'MAI-Receitas'!$F:$F)-SUMIF('MAI-Despesas'!$H:$H,$B$8,'MAI-Despesas'!$F:$F)-'Mov. entre Contas'!G13+'Mov. entre Contas'!G8 -> 3380.81 | I8: =H8+SUMIF('JUN-Receitas'!$H:$H,$B$8,'JUN-Receitas'!$F:$F)-SUMIF('JUN-Despesas'!$H:$H,$B$8,'JUN-Despesas'!$F:$F)-'Mov. entre Contas'!H13+'Mov. entre Contas'!H8 -> 2235.96 | J8: 158 | K8: =J8+SUMIF('AGO-Receitas'!$H:$H,$B$8,'AGO-Receitas'!$F:$F)-SUMIF('AGO-Despesas'!$H:$H,$B$8,'AGO-Despesas'!$F:$F)-'Mov. entre Contas'!J13+'Mov. entre Contas'!J8 -> 158 | L8: =K8+SUMIF('SET-Receitas'!$H:$H,$B$8,'SET-Receitas'!$F:$F)-SUMIF('SET-Despesas'!$H:$H,$B$8,'SET-Despesas'!$F:$F)-'Mov. entre Contas'!K13+'Mov. entre Contas'!K8 -> 158 | M8: =L8+SUMIF('OUT-Receitas'!$H:$H,$B$8,'OUT-Receitas'!$F:$F)-SUMIF('OUT-Despesas'!$H:$H,$B$8,'OUT-Despesas'!$F:$F)-'Mov. entre Contas'!L13+'Mov. entre Contas'!L8 -> 158 | N8: =M8+SUMIF('NOV-Receitas'!$H:$H,$B$8,'NOV-Receitas'!$F:$F)-SUMIF('NOV-Despesas'!$H:$H,$B$8,'NOV-Despesas'!$F:$F)-'Mov. entre Contas'!M13+'Mov. entre Contas'!M8 -> 158 | O8: =N8+SUMIF('DEZ-Receitas'!$H:$H,$B$8,'DEZ-Receitas'!$F:$F)-SUMIF('DEZ-Despesas'!$H:$H,$B$8,'DEZ-Despesas'!$F:$F)-'Mov. entre Contas'!N13+'Mov. entre Contas'!N8 -> 158

Sheet Distrib. Valores
B2: DISTRIB. VALORES | C2: SALDO ATUAL | D2: 2025
D3: JAN | E3: FEV | F3: MAR | G3: ABR | H3: MAI | I3: JUN | J3: JUL | K3: AGO | L3: SET | M3: OUT | N3: NOV | O3: DEZ
B4: SALDO | C4: =SUM(C6:C11) -> 9510.64 | D4: =D5-D13 -> -8051.61 | E4: =E5-E13 -> -464.58 | F4: =F5-F13 -> -3262.16 | G4: =G5-G13 -> 3222.13 | H4: =H5-H13 -> 3707.58 | I4: =I5-I13 -> 17231.67 | J4: =J5-J13 -> -17542.93 | K4: =K5-K13 -> 0 | ... O4: =O5-O13 -> 0
B5: Receita | C5: - | D5: =SUM(D6:D11) -> 49292.99 | E5: =SUM(E6:E11) -> 22658.55 | F5: =SUM(F6:F11) -> 25745.35 | G5: =SUM(G6:G11) -> 38989.99 | H5: =SUM(H6:H11) -> 22836.63 | I5: =SUM(I6:I11) -> 46977.33 | J5: =SUM(J6:J11) -> 35715 | K5: =SUM(K6:K11) -> 0 | ... O5: =SUM(O6:O11) -> 0
B6: Operacional Tesouraria | C6: =13572.08+SUM(D6:O6)-SUM(D14:O14)-SUM(D16:O16)-SUM(D17:O17) -> 36082.68 | D6: =('JAN-Receitas'!$F$6-'JAN-Receitas'!$P$6-'JAN-Receitas'!$Q$6-'JAN-Receitas'!$R$6-'JAN-Receitas'!$S$6-'JAN-Receitas'!$T$6)+'JAN-Receitas'!$F$127+'JAN-Receitas'!$F$148+'JAN-Receitas'!$F$168+'JAN-Receitas'!$F$172-('JAN-Receitas'!$F$166+'JAN-Receitas'!$F$167+'JAN-Receitas'!F169) -> 41929.63 | E6: =('FEV-Receitas'!$F$6-'FEV-Receitas'!$P$6-'FEV-Receitas'!$Q$6-'FEV-Receitas'!$R$6-'FEV-Receitas'!$S$6-'FEV-Receitas'!$T$6)+'FEV-Receitas'!$F$127+'FEV-Receitas'!$F$147+'FEV-Receitas'!$F$169+'FEV-Receitas'!$F$173 -> 21053.29 | F6: =('MAR-Receitas'!$F$6-'MAR-Receitas'!$P$6-'MAR-Receitas'!$Q$6-'MAR-Receitas'!$R$6-'MAR-Receitas'!$S$6-'MAR-Receitas'!$T$6)+'MAR-Receitas'!$F$127+'MAR-Receitas'!$F$151+'MAR-Receitas'!$F$175+'MAR-Receitas'!$F$179-('MAR-Receitas'!F140) -> 23479.41 | G6: =('ABR-Receitas'!$F$6-'ABR-Receitas'!$P$6-'ABR-Receitas'!$Q$6-'ABR-Receitas'!$R$6-'ABR-Receitas'!$S$6-'ABR-Receitas'!$T$6)+'ABR-Receitas'!$F$126+'ABR-Receitas'!$F$150+'ABR-Receitas'!$F$180+'ABR-Receitas'!$F$184-('ABR-Receitas'!$F126) -> 22380.86 | H6: =('MAI-Receitas'!$F$6-'MAI-Receitas'!$P$6-'MAI-Receitas'!$Q$6-'MAI-Receitas'!$R$6-'MAI-Receitas'!$S$6-'MAI-Receitas'!$T$6)+'MAI-Receitas'!$F$124+'MAI-Receitas'!$F$149+'MAI-Receitas'!$F$179+'MAI-Receitas'!$F$183 -> 21585.89 | I6: =('JUN-Receitas'!$F$6-'JUN-Receitas'!$P$6-'JUN-Receitas'!$Q$6-'JUN-Receitas'!$R$6-'JUN-Receitas'!$S$6-'JUN-Receitas'!$T$6)+'JUN-Receitas'!$F$126+'JUN-Receitas'!$F$152+'JUN-Receitas'!$F$182+'JUN-Receitas'!$F$186-('JUN-Receitas'!$F126) -> 18361.6 | J6: =('JUL-Receitas'!$F$6-'JUL-Receitas'!$P$6-'JUL-Receitas'!$Q$6-'JUL-Receitas'!$R$6-'JUL-Receitas'!$S$6-'JUL-Receitas'!$T$6)+'JUL-Receitas'!$F$7+'JUL-Receitas'!$F$16+'JUL-Receitas'!$F$25+'JUL-Receitas'!$F$29-('JUL-Receitas'!$F12)-'JUL-Receitas'!F27 -> 20599.94 | K6: =('AGO-Receitas'!$F$6-'AGO-Receitas'!$P$6-'AGO-Receitas'!$Q$6-'AGO-Receitas'!$R$6-'AGO-Receitas'!$S$6-'AGO-Receitas'!$T$6)+'AGO-Receitas'!$F$126+'AGO-Receitas'!$F$154+'AGO-Receitas'!$F$184+'AGO-Receitas'!$F$188-('AGO-Receitas'!$F$170+'AGO-Receitas'!$F171+'AGO-Receitas'!$F$172+'AGO-Receitas'!$F139+'AGO-Receitas'!$F146) -> 0 | L6: =('SET-Receitas'!$F$6-'SET-Receitas'!$P$6-'SET-Receitas'!$Q$6-'SET-Receitas'!$R$6-'SET-Receitas'!$S$6-'SET-Receitas'!$T$6)+'SET-Receitas'!$F$126+'SET-Receitas'!$F$154+'SET-Receitas'!$F$184+'SET-Receitas'!$F$188-('SET-Receitas'!$F171+'SET-Receitas'!$F$172+'SET-Receitas'!$F139+'SET-Receitas'!$F146)-'SET-Receitas'!$F184 -> 0 | M6: =('OUT-Receitas'!$F$6-'OUT-Receitas'!$P$6-'OUT-Receitas'!$Q$6-'OUT-Receitas'!$R$6-'OUT-Receitas'!$S$6-'OUT-Receitas'!$T$6)+'OUT-Receitas'!$F$126+'OUT-Receitas'!$F$154+'OUT-Receitas'!$F$184+'OUT-Receitas'!$F$188-('OUT-Receitas'!$F171+'OUT-Receitas'!$F$172+'OUT-Receitas'!$F139+'OUT-Receitas'!$F146)-'OUT-Receitas'!$F184-'OUT-Receitas'!$F170 -> 0 | N6: =('NOV-Receitas'!$F$6-'NOV-Receitas'!$P$6-'NOV-Receitas'!$Q$6-'NOV-Receitas'!$R$6-'NOV-Receitas'!$S$6-'NOV-Receitas'!$T$6)+'NOV-Receitas'!$F$125+'NOV-Receitas'!$F$153+'NOV-Receitas'!$F$183+'NOV-Receitas'!$F$187-('NOV-Receitas'!$F170+'NOV-Receitas'!$F$171+'NOV-Receitas'!$F138+'NOV-Receitas'!$F145)-'NOV-Receitas'!$F183-'NOV-Receitas'!F169 -> 0 | O6: =('DEZ-Receitas'!$F$6-'DEZ-Receitas'!$P$6-'DEZ-Receitas'!$Q$6-'DEZ-Receitas'!$R$6-'DEZ-Receitas'!$S$6-'DEZ-Receitas'!$T$6)+'DEZ-Receitas'!$F$125+'DEZ-Receitas'!$F$154+'DEZ-Receitas'!$F$184+'DEZ-Receitas'!$F$188-('DEZ-Receitas'!$F170+'DEZ-Receitas'!$F171+'DEZ-Receitas'!$F$172+'DEZ-Receitas'!$F173+'DEZ-Receitas'!$F139+'DEZ-Receitas'!$F146+'DEZ-Receitas'!$F184+'DEZ-Receitas'!$F129) -> 0
B7: Beneficência NLT | C7: =834.599999999999+SUM(D7:O7)-SUM(D18:O18) -> 1020.91 | D7: ='JAN-Receitas'!$P$6 -> 152.36 | E7: ='FEV-Receitas'!$P$6 -> 223.26 | F7: ='MAR-Receitas'!$P$6 -> 178.94 | G7: ='ABR-Receitas'!$P$6 -> 191.76 | H7: ='MAI-Receitas'!$P$6 -> 178.74 | I7: ='JUN-Receitas'!$P$6 -> 212.32 | J7: ='JUL-Receitas'!$P$6 -> 179.06 | K7: ='AGO-Receitas'!$P$6 -> 0 | L7: ='SET-Receitas'!$P$6+('SET-Receitas'!$F$171+'SET-Receitas'!$F$172) -> 0 | M7: ='OUT-Receitas'!$P$6+('OUT-Receitas'!$F$171+'OUT-Receitas'!$F$172)+'OUT-Receitas'!$F170 -> 0 | N7: ='NOV-Receitas'!$P$6+('NOV-Receitas'!$F$170+'NOV-Receitas'!$F$171) -> 0 | O7: ='DEZ-Receitas'!$P$6+('DEZ-Receitas'!$F$171+'DEZ-Receitas'!$F$172) -> 0
B8: Novo Encanto NLT | C8: =903.41+SUM(D8:O8)-SUM(D19:O19)-SUM(D15:O15) -> 1370.41 | D8: ='JAN-Receitas'!$Q$6 -> 155 | E8: ='FEV-Receitas'!$Q$6 -> 215 | F8: ='MAR-Receitas'!$Q$6 -> 170 | G8: ='ABR-Receitas'!$Q$6 -> 190 | H8: ='MAI-Receitas'!$Q$6 -> 150 | I8: ='JUN-Receitas'!$Q$6 -> 195 | J8: ='JUL-Receitas'!$Q$6 -> 160 | K8: ='AGO-Receitas'!$Q$6 -> 0 | L8: ='SET-Receitas'!$Q$6 -> 0 | M8: ='OUT-Receitas'!$Q$6 -> 0 | N8: ='NOV-Receitas'!$Q$6 -> 0 | O8: ='DEZ-Receitas'!$Q$6 -> 0
B9: Plantio NLT | C9: =2242.53+SUM(D9:O9)-SUM(D20:O20) -> 866.53 | D9: ='JAN-Receitas'!$R$6+('JAN-Receitas'!$F$166+'JAN-Receitas'!$F$167) -> 259 | E9: ='FEV-Receitas'!$R$6 -> 260 | F9: ='MAR-Receitas'!$R$6 -> 205 | G9: ='ABR-Receitas'!$R$6 -> 210 | H9: ='MAI-Receitas'!$R$6 -> 175 | I9: ='JUN-Receitas'!$R$6 -> 195 | J9: ='JUL-Receitas'!$R$6 -> 160 | K9: ='AGO-Receitas'!$R$6+('AGO-Receitas'!$F$170+'AGO-Receitas'!$F$171+'AGO-Receitas'!$F$172) -> 0 | L9: ='SET-Receitas'!$R$6 -> 0 | M9: ='OUT-Receitas'!$R$6 -> 0 | N9: ='NOV-Receitas'!$R$6 -> 0 | O9: ='DEZ-Receitas'!$R$6 -> 0
B10: Fundo de Reserva Bilhete Aéreo | C10: =1500.49+SUM(D10:O10)-SUM(D21:O21) -> 626.65 | D10: ='JAN-Receitas'!$S$6 -> 217 | E10: ='FEV-Receitas'!$S$6 -> 297 | F10: ='MAR-Receitas'!$S$6 -> 262 | G10: ='ABR-Receitas'!$S$6 -> 297 | H10: ='MAI-Receitas'!$S$6 -> 227 | I10: ='JUN-Receitas'!$S$6 -> 307 | J10: ='JUL-Receitas'!$S$6+'JUL-Receitas'!F27 -> 1072 | K10: ='AGO-Receitas'!$S$6 -> 0 | L10: ='SET-Receitas'!$S$6 -> 0 | M10: ='OUT-Receitas'!$S$6 -> 0 | N10: ='NOV-Receitas'!$S$6 -> 0 | O10: ='DEZ-Receitas'!$S$6 -> 0
B11: Fundo de Reserva Construção | C11: =-4382.56999999995+SUM(D11:O11)-SUM(D22:O22) -> -30456.54 | D11: ='JAN-Receitas'!$T$6+'JAN-Receitas'!F169 -> 6580 | E11: ='FEV-Receitas'!$T$6 -> 610 | F11: ='MAR-Receitas'!$T$6+'MAR-Receitas'!F140 -> 1450 | G11: ='ABR-Receitas'!$T$6+'ABR-Receitas'!$F126 -> 15720.37 | H11: ='MAI-Receitas'!$T$6 -> 520 | I11: ='JUN-Receitas'!$T$6+'JUN-Receitas'!$F126 -> 27706.41 | J11: ='JUL-Receitas'!$T$6+'JUL-Receitas'!$F12 -> 13544 | K11: ='AGO-Receitas'!$T$6+'AGO-Receitas'!$F139+'AGO-Receitas'!$F146 -> 0 | L11: ='SET-Receitas'!$T$6+'SET-Receitas'!$F139+'SET-Receitas'!$F146+'SET-Receitas'!$F184 -> 0 | M11: ='OUT-Receitas'!$T$6+'OUT-Receitas'!$F139+'OUT-Receitas'!$F146+'OUT-Receitas'!$F184 -> 0 | N11: ='NOV-Receitas'!$T$6+'NOV-Receitas'!$F138+'NOV-Receitas'!$F145+'NOV-Receitas'!$F183+'NOV-Receitas'!F169 -> 0 | O11: ='DEZ-Receitas'!$T$6+'DEZ-Receitas'!$F170+'DEZ-Receitas'!$F171+'DEZ-Receitas'!$F$172+'DEZ-Receitas'!$F173+'DEZ-Receitas'!$F139+'DEZ-Receitas'!$F146+'DEZ-Receitas'!$F184+'DEZ-Receitas'!$F129 -> 0
B13: Despesa | C13: - | D13: =SUM(D14:D22) -> 57344.6 | E13: =SUM(E14:E22) -> 23123.13 | F13: =SUM(F14:F22) -> 29007.51 | G13: =SUM(G14:G22) -> 35767.86 | H13: =SUM(H14:H22) -> 19129.05 | I13: =SUM(I14:I22) -> 29745.66 | J13: =SUM(J14:J22) -> 53257.93 | K13: =SUM(K14:K22) -> 0 | ... O13: =SUM(O14:O22) -> 0
B14: Operacional Tesouraria | C14: - | D14: ='JAN-Despesas'!$F$6+SUM('JAN-Despesas'!$F$17:$F$28)+'JAN-Despesas'!$F$34+'JAN-Despesas'!$F$38+'JAN-Despesas'!$F$63+'JAN-Despesas'!$F$93+'JAN-Despesas'!$F$108+'JAN-Despesas'!$F$160+'JAN-Despesas'!$F$166+'JAN-Despesas'!$F$182+'JAN-Despesas'!$F$192+'JAN-Despesas'!$F$222+'JAN-Despesas'!$F$271+'JAN-Despesas'!$F$32 -> 36029.6 | E14: ='FEV-Despesas'!$F$6+SUM('FEV-Despesas'!$F$17:$F$28)+'FEV-Despesas'!$F$34+'FEV-Despesas'!$F$38+'FEV-Despesas'!$F$63+'FEV-Despesas'!$F$93+'FEV-Despesas'!$F$119+'FEV-Despesas'!$F$174+'FEV-Despesas'!$F$180+'FEV-Despesas'!$F$196+'FEV-Despesas'!$F$206+'FEV-Despesas'!$F$236+'FEV-Despesas'!$F$277+'FEV-Despesas'!$F$32 -> 16504.07 | F14: ='MAR-Despesas'!$F$6+SUM('MAR-Despesas'!$F$17:$F$28)+'MAR-Despesas'!$F$34+'MAR-Despesas'!$F$38+'MAR-Despesas'!$F$63+'MAR-Despesas'!$F$93+'MAR-Despesas'!$F$119+'MAR-Despesas'!$F$173+'MAR-Despesas'!$F$179+'MAR-Despesas'!$F$195+'MAR-Despesas'!$F$205+'MAR-Despesas'!$F$235+'MAR-Despesas'!$F$276+'MAR-Despesas'!$F$32+'MAR-Despesas'!$F$33 -> 17840.75 | G14: ='ABR-Despesas'!$F$6+SUM('ABR-Despesas'!$F$17:$F$28)+'ABR-Despesas'!$F$34+'ABR-Despesas'!$F$38+'ABR-Despesas'!$F$63+'ABR-Despesas'!$F$85+'ABR-Despesas'!$F$111+'ABR-Despesas'!$F$169+'ABR-Despesas'!$F$175+'ABR-Despesas'!$F$214+'ABR-Despesas'!$F$224+'ABR-Despesas'!$F$254+'ABR-Despesas'!$F$305+'ABR-Despesas'!$F$32-'ABR-Despesas'!F285-'ABR-Despesas'!F175+'ABR-Despesas'!F33 -> 14473.15 | H14: ='MAI-Despesas'!$F$6+SUM('MAI-Despesas'!$F$17:$F$28)+'MAI-Despesas'!$F$34+'MAI-Despesas'!$F$38+'MAI-Despesas'!$F$63+'MAI-Despesas'!$F$87+'MAI-Despesas'!$F$113+'MAI-Despesas'!$F$183+'MAI-Despesas'!$F$189+'MAI-Despesas'!$F$228+'MAI-Despesas'!$F$238+'MAI-Despesas'!$F$268+'MAI-Despesas'!$F$319+'MAI-Despesas'!$F$32 -> 14836.44 | I14: ='JUN-Despesas'!$F$6+SUM('JUN-Despesas'!$F$17:$F$28)+'JUN-Despesas'!$F$33+'JUN-Despesas'!$F$34+'JUN-Despesas'!$F$38+'JUN-Despesas'!$F$63+'JUN-Despesas'!$F$87+'JUN-Despesas'!$F$113+'JUN-Despesas'!$F$174+'JUN-Despesas'!$F$180+'JUN-Despesas'!$F$219+'JUN-Despesas'!$F$229+'JUN-Despesas'!$F$259+'JUN-Despesas'!$F$310+'JUN-Despesas'!$F$32-'JUN-Despesas'!$F$259 -> 14405.45 | J14: ='JUL-Despesas'!$F$6+SUM('JUL-Despesas'!$F$13:$F$18)+'JUL-Despesas'!$F$22+'JUL-Despesas'!$F$24+'JUL-Despesas'!$F$32+'JUL-Despesas'!$F$52+'JUL-Despesas'!$F$70+'JUL-Despesas'!$F$87+'JUL-Despesas'!$F$93+'JUL-Despesas'!$F$21-'JUL-Despesas'!$F$92 -> 20703.1 | K14: ='AGO-Despesas'!$F$6+SUM('AGO-Despesas'!$F$17:$F$27)+'AGO-Despesas'!$F$33+'AGO-Despesas'!$F$37+'AGO-Despesas'!$F$62+'AGO-Despesas'!$F$89+'AGO-Despesas'!$F$115+'AGO-Despesas'!$F$176+'AGO-Despesas'!$F$182+'AGO-Despesas'!$F$221+'AGO-Despesas'!$F$231+'AGO-Despesas'!$F$261+'AGO-Despesas'!$F$324+'AGO-Despesas'!$F$31-'AGO-Despesas'!$F$292-'AGO-Despesas'!$F$315 -> 0 | L14: ='SET-Despesas'!$F$6+SUM('SET-Despesas'!$F$17:$F$27)+'SET-Despesas'!$F$33+'SET-Despesas'!$F$37+'SET-Despesas'!$F$62+'SET-Despesas'!$F$89+'SET-Despesas'!$F$115+'SET-Despesas'!$F$176+'SET-Despesas'!$F$182+'SET-Despesas'!$F$221+'SET-Despesas'!$F$231+'SET-Despesas'!$F$261+'SET-Despesas'!$F$324+'SET-Despesas'!$F$31-'SET-Despesas'!$F$292-'SET-Despesas'!$F$315 -> 0 | M14: ='OUT-Despesas'!$F$6+SUM('OUT-Despesas'!$F$17:$F$27)+'OUT-Despesas'!$F$33+'OUT-Despesas'!$F$37+'OUT-Despesas'!$F$62+'OUT-Despesas'!$F$89+'OUT-Despesas'!$F$115+'OUT-Despesas'!$F$176+'OUT-Despesas'!$F$182+'OUT-Despesas'!$F$221+'OUT-Despesas'!$F$231+'OUT-Despesas'!$F$261+'OUT-Despesas'!$F$324+'OUT-Despesas'!$F$31+'OUT-Despesas'!$F$32-'OUT-Despesas'!$F$292-'OUT-Despesas'!$F$315 -> 0 | N14: ='NOV-Despesas'!$F$6+SUM('NOV-Despesas'!$F$17:$F$28)+'NOV-Despesas'!$F$34+'NOV-Despesas'!$F$38+'NOV-Despesas'!$F$63+'NOV-Despesas'!$F$90+'NOV-Despesas'!$F$116+'NOV-Despesas'!$F$179+'NOV-Despesas'!$F$185+'NOV-Despesas'!$F$224+'NOV-Despesas'!$F$234+'NOV-Despesas'!$F$264+'NOV-Despesas'!$F$327+'NOV-Despesas'!$F$32+'NOV-Despesas'!$F$33-'NOV-Despesas'!$F$295-'NOV-Despesas'!$F$318-'NOV-Despesas'!F35 -> 0 | O14: ='DEZ-Despesas'!$F$6+SUM('DEZ-Despesas'!$F$17:$F$28)+'DEZ-Despesas'!$F$34+'DEZ-Despesas'!$F$38+'DEZ-Despesas'!$F$63+'DEZ-Despesas'!$F$90+'DEZ-Despesas'!$F$116+'DEZ-Despesas'!$F$179+'DEZ-Despesas'!$F$185+'DEZ-Despesas'!$F$224+'DEZ-Despesas'!$F$234+'DEZ-Despesas'!$F$327+'DEZ-Despesas'!$F$32+'DEZ-Despesas'!$F$33 -> 0
B15: Repasse Novo encanto | D15: ='JAN-Despesas'!$F$29 -> 117 | E15: ='FEV-Despesas'!$F$29 -> 84 | F15: ='MAR-Despesas'!$F$29 -> 117 | G15: ='ABR-Despesas'!$F$29 -> 117 | H15: ='MAI-Despesas'!$F$29 -> 108 | I15: ='JUN-Despesas'!$F$29 -> 108 | J15: ='JUL-Despesas'!$F$19 -> 117 | K15: ='AGO-Despesas'!$F$28 -> 0 | L15: ='SET-Despesas'!$F$28 -> 0 | M15: ='OUT-Despesas'!$F$28 -> 0 | N15: ='NOV-Despesas'!$F$29 -> 0 | O15: ='DEZ-Despesas'!$F$29 -> 0
B16: Repasse Flor Divina | D16: ='JAN-Despesas'!$F$30 -> 2263.27 | E16: ='FEV-Despesas'!$F$30 -> 0 | F16: ='MAR-Despesas'!$F$30 -> 2048 | G16: ='ABR-Despesas'!$F$30 -> 2095.3 | H16: ='MAI-Despesas'!$F$30 -> 2289.32 | I16: ='JUN-Despesas'!$F$30 -> 0 | J16: ='JUL-Despesas'!$F$20 -> 1469.75 | K16: ='AGO-Despesas'!$F$29 -> 0 | L16: ='SET-Despesas'!$F$29 -> 0 | M16: ='OUT-Despesas'!$F$29 -> 0 | N16: ='NOV-Despesas'!$F$30 -> 0 | O16: ='DEZ-Despesas'!$F$30 -> 0
B17: Repasse Memorial José Gabriel da Costa | D17: ='JAN-Despesas'!$F$31 -> 0 | E17: ='FEV-Despesas'!$F$31 -> 0 | F17: ='MAR-Despesas'!$F$31 -> 1921.82 | G17: ='ABR-Despesas'!$F$31 -> 0 | H17: ='MAI-Despesas'!$F$31 -> 0 | I17: ='JUN-Despesas'!$F$31 -> 0 | J17: 0 | K17: ='AGO-Despesas'!$F$30 -> 0 | L17: ='SET-Despesas'!$F$30 -> 0 | M17: ='OUT-Despesas'!$F$30 -> 0 | N17: ='NOV-Despesas'!$F$31 -> 0 | O17: ='DEZ-Despesas'!$F$31 -> 0
B18: Beneficência NLT | D18: ='JAN-Despesas'!$F$172 -> 0 | E18: ='FEV-Despesas'!$F$186 -> 100 | F18: ='MAR-Despesas'!$F$185 -> 100 | G18: ='ABR-Despesas'!$F$204 -> 100 | H18: ='MAI-Despesas'!$F$218 -> 100 | I18: ='JUN-Despesas'!$F$209 -> 630.13 | J18: ='JUL-Despesas'!$F$82 -> 100 | K18: ='AGO-Despesas'!$F$211 -> 0 | L18: ='SET-Despesas'!$F$211 -> 0 | M18: ='OUT-Despesas'!$F$211 -> 0 | N18: ='NOV-Despesas'!$F$214 -> 0 | O18: ='DEZ-Despesas'!$F$214 -> 0
B19: Novo Encanto NLT | D19: ='JAN-Despesas'!$F$213 -> 0 | E19: ='FEV-Despesas'!$F$227 -> 0 | F19: ='MAR-Despesas'!$F$226 -> 0 | G19: ='ABR-Despesas'!$F$245 -> 0 | H19: ='MAI-Despesas'!$F$258 -> 0 | I19: ='JUN-Despesas'!$F$250 -> 0 | J19: 0 | K19: ='AGO-Despesas'!$F$251 -> 0 | L19: ='SET-Despesas'!$F$251 -> 0 | M19: ='OUT-Despesas'!$F$251 -> 0 | N19: ='NOV-Despesas'!$F$254 -> 0 | O19: ='DEZ-Despesas'!$F$254 -> 0
B20: Plantio NLT | D20: ='JAN-Despesas'!$F$202 -> 160 | E20: ='FEV-Despesas'!$F$216 -> 0 | F20: ='MAR-Despesas'!$F$215 -> 800 | G20: ='ABR-Despesas'!$F$234 -> 1240 | H20: ='MAI-Despesas'!$F$248 -> 80 | I20: ='JUN-Despesas'!$F$239 -> 400 | J20: ='JUL-Despesas'!$F$84 -> 160 | K20: ='AGO-Despesas'!$F$241 -> 0 | L20: ='SET-Despesas'!$F$241 -> 0 | M20: ='OUT-Despesas'!$F$241 -> 0 | N20: ='NOV-Despesas'!$F$244 -> 0 | O20: ='DEZ-Despesas'!$F$244 -> 0
B21: Fundo de Reserva Bilhete Aéreo | D21: ='JAN-Despesas'!$F$125 -> 0 | E21: ='FEV-Despesas'!$F$137 -> 513.21 | F21: ='MAR-Despesas'!$F$136 -> 513.21 | G21: ='ABR-Despesas'!$F$134 -> 513.21 | H21: ='MAI-Despesas'!$F$148 -> 513.21 | I21: ='JUN-Despesas'!$F$139 -> 0 | J21: ='JUL-Despesas'!$F$61 -> 1500 | K21: ='AGO-Despesas'!$F$141 -> 0 | L21: ='SET-Despesas'!$F$141 -> 0 | M21: ='OUT-Despesas'!$F$141 -> 0 | N21: ='NOV-Despesas'!$F$144 -> 0 | O21: ='DEZ-Despesas'!$F$144 -> 0
B22: Fundo de Reserva Construção | D22: ='JAN-Despesas'!$F$135 -> 18774.73 | E22: ='FEV-Despesas'!$F$147 -> 5921.85 | F22: ='MAR-Despesas'!$F$146 -> 5666.73 | G22: ='ABR-Despesas'!$F$144+'ABR-Despesas'!F285+'ABR-Despesas'!F175 -> 17229.2 | H22: ='MAI-Despesas'!$F$158 -> 1202.08 | I22: ='JUN-Despesas'!$F$149+'JUN-Despesas'!$F$259 -> 14202.08 | J22: ='JUL-Despesas'!$F$64+'JUL-Despesas'!$F$92 -> 29208.08 | K22: ='AGO-Despesas'!$F$151+'AGO-Despesas'!$F$292+'AGO-Despesas'!$F$315 -> 0 | L22: ='SET-Despesas'!$F$151+'SET-Despesas'!$F$292+'SET-Despesas'!$F$315 -> 0 | M22: ='OUT-Despesas'!$F$151+'OUT-Despesas'!$F$292+'OUT-Despesas'!$F$315 -> 0 | N22: ='NOV-Despesas'!$F$154+'NOV-Despesas'!$F$295+'NOV-Despesas'!$F$318+'NOV-Despesas'!$F$35 -> 0 | O22: ='DEZ-Despesas'!$F$154+'DEZ-Despesas'!$F$264 -> 0
B24: Observação:

Sheet Dinheiro
B2: MOV. EM DINHEIRO | C2: SALDO ATUAL | D2: 2025
D3: JAN | E3: FEV | F3: MAR | G3: ABR | H3: MAI | I3: JUN | J3: JUL | K3: AGO | L3: SET | M3: OUT | N3: NOV | O3: DEZ
B4: SALDO | C4: =2724.62+SUM(D4:O4) -> 614.2 | D4: =D5-D16 -> 2809.58 | E4: =E5-E16 -> -3850 | F4: =F5-F16 -> -957 | G4: =G5-G16 -> -305 | H4: =H5-H16 -> 112 | I4: =I5-I16 -> 80 | J4: =J5-J16 -> 0 | K4: =K5-K16 -> 0 | ... O4: =O5-O16 -> 0
B5: Receita | C5: - | D5: =SUM(D6:D14) -> 6477.08 | E5: =SUM(E6:E14) -> 150 | F5: =SUM(F6:F14) -> 43 | G5: =SUM(G6:G14) -> 3032 | H5: =SUM(H6:H14) -> 112 | I5: =SUM(I6:I14) -> 80 | J5: =SUM(J6:J14) -> 0 | K5: =SUM(K6:K14) -> 0 | ... O5: =SUM(O6:O14) -> 0
B6: Recebimento Mensalidade | D6: 0 | E6: 0 | F6: 0 | G6: 0 | H6: 0 | I6: 0 | J6: 0 | K6: 0 | L6: 0 | M6: 0 | N6: 0 | O6: 0
B7: 1a Escala - Caixa jantar | D7: ='JAN-Receitas'!F156 -> 20 | E7: ='FEV-Receitas'!F155 -> 40 | F7: 0 | G7: ='MAI-Receitas'!F157 -> 0 | H7: 0 | I7: 10 | J7: 0 | K7: 0 | L7: 0 | M7: 0 | N7: 0 | O7: 0
B8: 2a Escala - Caixa jantar | D8: ='JAN-Receitas'!$F158 -> 20 | E8: ='FEV-Receitas'!F157 -> 20 | F8: ='MAR-Receitas'!F161 -> 10 | G8: 0 | H8: ='MAI-Receitas'!F159 -> 10 | I8: 30 | J8: 0 | K8: 0 | L8: 0 | M8: 0 | N8: 0 | O8: 0
B9: 1a Escala - Caixa da boa vontade | D9: ='JAN-Receitas'!F151 -> 114 | E9: ='FEV-Receitas'!F150 -> 0 | F9: ='MAR-Receitas'!F154 -> 5 | G9: ='MAI-Receitas'!F152 -> 0 | H9: 0 | I9: 40 | J9: 0 | K9: 0 | L9: 0 | M9: 0 | N9: 0 | O9: 0
B10: 2a Escala - Caixa da boa vontade | D10: ='JAN-Receitas'!F153 -> 35 | E10: ='FEV-Receitas'!F152 -> 90 | F10: ='MAR-Receitas'!F156 -> 27 | G10: 0 | H10: ='MAI-Receitas'!F154 -> 102 | I10: 0 | J10: 0 | K10: 0 | L10: 0 | M10: 0 | N10: 0 | O10: 0
B11: Outras receitas | D11: 0 | E11: 0 | F11: ='MAR-Receitas'!F164 -> 1 | G11: 400 | H11: 0 | I11: 0 | J11: 0 | K11: 0 | L11: 0 | M11: 0 | N11: 0 | O11: 0
B12: Outras receitas | D12: 0 | E12: 0 | F12: 0 | G12: 0 | H12: 0 | I12: 0 | J12: 0 | K12: 0 | L12: 0 | M12: 0 | N12: 0 | O12: 0
B13: Promoção | D13: ='JAN-Receitas'!F138 -> 5423.14 | E13: 0 | F13: 0 | G13: ='ABR-Receitas'!F144 -> 2632 | H13: 0 | I13: 0 | J13: 0 | K13: 0 | L13: 0 | M13: 0 | N13: 0 | O13: 0
B14: Doação | D14: ='JAN-Receitas'!F170 -> 864.94 | E14: 0 | F14: 0 | G14: 0 | H14: 0 | I14: 0 | J14: 0 | K14: 0 | L14: 0 | M14: 0 | N14: 0 | O14: 0
B16: Despesa | C16: - | D16: =SUM(D17:D24) -> 3667.5 | E16: =SUM(E17:E24) -> 4000 | F16: =SUM(F17:F24) -> 1000 | G16: =SUM(G17:G24) -> 3337 | H16: =SUM(H17:H24) -> 0 | I16: =SUM(I17:I24) -> 0 | J16: =SUM(J17:J24) -> 0 | K16: =SUM(K17:K24) -> 0 | ... O16: =SUM(O17:O24) -> 0
B17: Cantina SANA | D17: ='JAN-Despesas'!F245 -> 1650 | E17: 0 | F17: 0 | G17: 0 | H17: 0 | I17: 0 | J17: 0 | K17: 0 | L17: 0 | M17: 0 | N17: 0 | O17: 0
B18: Cantina SANA | D18: ='JAN-Despesas'!F246 -> 1237.5 | E18: 0 | F18: 0 | G18: 0 | H18: 0 | I18: 0 | J18: 0 | K18: 0 | L18: 0 | M18: 0 | N18: 0 | O18: 0
B19: Cantina SANA | D19: ='JAN-Despesas'!F260 -> 780 | E19: 0 | F19: 0 | G19: 0 | H19: 0 | I19: 0 | J19: 0 | K19: 0 | L19: 0 | M19: 0 | N19: 0 | O19: 0
B20: Outras despesas | D20: 0 | E20: 0 | F20: 0 | G20: 0 | H20: 0 | I20: 0 | J20: 0 | K20: 0 | L20: 0 | M20: 0 | N20: 0 | O20: 0
B21: Outras despesas | D21: 0 | E21: 0 | F21: 0 | G21: 0 | H21: 0 | I21: 0 | J21: 0 | K21: 0 | L21: 0 | M21: 0 | N21: 0 | O21: 0
B22: Outras despesas | D22: 0 | E22: 0 | F22: 0 | G22: 0 | H22: 0 | I22: 0 | J22: 0 | K22: 0 | L22: 0 | M22: 0 | N22: 0 | O22: 0
B23: Outras despesas | D23: 0 | E23: 0 | F23: 0 | G23: 0 | H23: 0 | I23: 0 | J23: 0 | K23: 0 | L23: 0 | M23: 0 | N23: 0 | O23: 0
B24: Depósito | D24: 0 | E24: 4000 | F24: 1000 | G24: =1337+2000 -> 3337 | H24: 0 | I24: 0 | J24: 0 | K24: 0 | L24: 0 | M24: 0 | N24: 0 | O24: 0
B26: Observações do mês:

Sheet Mov. entre Contas
B2: MOVIM. ENTRE CONTAS | C2: 2025
C3: JAN | D3: FEV | E3: MAR | F3: ABR | G3: MAI | H3: JUN | I3: JUL | J3: AGO | K3: SET | L3: OUT | M3: NOV | N3: DEZ
B4: SALDO | C4: =C5-C10 -> 0 | D4: =D5-D10 -> 4000 | E4: =E5-E10 -> 1000 | F4: =F5-F10 -> 3337 | G4: =G5-G10 -> 0 | H4: =H5-H10 -> 0 | I4: =I5-I10 -> 0 | J4: =J5-J10 -> 0 | ... N4: =N5-N10 -> 0
B5: Entrada | C5: =SUM(C6:C8) -> 7034.94 | D5: =SUM(D6:D8) -> 6956.56 | E5: =SUM(E6:E8) -> 4518.74 | F5: =SUM(F6:F8) -> 16237 | G5: =SUM(G6:G8) -> 1779.61 | H5: =SUM(H6:H8) -> 996.67 | I5: =SUM(I6:I8) -> 4549.8 | J5: =SUM(J6:J8) -> 0 | ... N5: =SUM(N6:N8) -> 0
B6: Banco - Cora | C6: =391.94+1788+4500 -> 6679.94 | D6: =4000+701+2255.56 -> 6956.56 | E6: =1000+2500+906.74 -> 4406.74 | F6: =900+12000+1337+2000 -> 16237 | G6: =1779.61 -> 1779.61 | H6: =160+452.14+354.28 -> 966.42 | I6: =354.88+759.76 -> 1114.64 | J6: 0 | K6: 0 | L6: 0 | M6: 0 | N6: 0
B7: Banco - Pagbank | C7: 355 | D7: 0 | E7: 112 | F7: 0 | G7: 0 | H7: 0 | I7: 3435.16 | J7: 0 | K7: 0 | L7: 0 | M7: 0 | N7: 0
B8: Banco - Stone | C8: 0 | D8: 0 | E8: 0 | F8: 0 | G8: 0 | H8: =18.75+11.5 -> 30.25 | I8: 0 | J8: 0 | K8: 0 | L8: 0 | M8: 0 | N8: 0
B10: Saída | C10: =SUM(C11:C13) -> 7034.94 | D10: =SUM(D11:D13) -> 2956.56 | E10: =SUM(E11:E13) -> 3518.74 | F10: =SUM(F11:F13) -> 12900 | G10: =SUM(G11:G13) -> 1779.61 | H10: =SUM(H11:H13) -> 996.67 | I10: =SUM(I11:I13) -> 4549.8 | J10: =SUM(J11:J13) -> 0 | ... N10: =SUM(N11:N13) -> 0
B11: Banco - Cora | C11: 0 | D11: 0 | E11: 0 | F11: 0 | G11: 0 | H11: 0 | I11: 0 | J11: 0 | K11: 0 | L11: 0 | M11: 0 | N11: 0
B12: Banco - Pagbank | C12: =391.94+4500 -> 4891.94 | D12: =2255.56 -> 2255.56 | E12: =906.74 -> 906.74 | F12: =12000 -> 12000 | G12: =1779.61 -> 1779.61 | H12: =160+452.14+18.75+11.5+354.28 -> 996.67 | I12: 0 | J12: 0 | K12: 0 | L12: 0 | M12: 0 | N12: 0
B13: Banco - Stone | C13: =355+1788 -> 2143 | D13: 701 | E13: =2500+112 -> 2612 | F13: 900 | G13: 0 | H13: 0 | I13: =354.88+759.76+3435.16 -> 4549.8 | J13: 0 | K13: 0 | L13: 0 | M13: 0 | N13: 0
B15: Observações do mês:

Sheet 2023-DEZ-RECEITAS
B2: RECEITAS
B4: TOTAL | E4: =SUM(E6,E127,E147,E166,E170) -> 13054.13 | F4: =SUM(F6,F127,F147,F166,F170) -> 16583.84 | H4: CAIXA | I4: PLANO DE CONTAS DG
C5: Data | D5: Efetivado | E5: Valor Previsto | F5: Valor Recebido | G5: Observação | J5: Inadimp. (qtd) | K5: Inadimp. (R$) | L5: Núcleo | M5: Repasse DG | N5: Repasse 11a R | O5: Benef. NLT | P5: NE NLT | Q5: Plantio NLT | R5: FR Bilhete Aéreo | S5: FR Construção | T5: Taxa Extra | U5: Detalhamento Taxa Extra | W5: A receber:
B6: Mensalidade | C6: 10 | D6: - | E6: =SUM(E7:E126) -> 13054.13 | F6: =SUM(F7:F126) -> 13681.15 | G6: - | J6: =(COUNTIF(D7:D126,"Pendente")+COUNTIF(D7:D126,"Parcial"))/COUNTA(B7:B126) -> 0.13131313 | K6: =IFERROR(-(W6/E6),"Pendente info") -> 0.099068264 | L6: =SUMIF($D$7:$D$126,"OK",L7:L126)+SUMIF($D$7:$D$126,"Parcial",L7:L126) -> 8523.3 | M6: =SUMIF($D$7:$D$126,"OK",M7:M126)+SUMIF($D$7:$D$126,"Parcial",M7:M126) -> 2186.73 | N6: =SUMIF($D$7:$D$126,"OK",N7:N126)+SUMIF($D$7:$D$126,"Parcial",N7:N126) -> 1157 | O6: =SUMIF($D$7:$D$126,"OK",O7:O126)+SUMIF($D$7:$D$126,"Parcial",O7:O126) -> 224.12 | P6: =SUMIF($D$7:$D$126,"OK",P7:P126)+SUMIF($D$7:$D$126,"Parcial",P7:P126) -> 150 | Q6: =SUMIF($D$7:$D$126,"OK",Q7:Q126)+SUMIF($D$7:$D$126,"Parcial",Q7:Q126) -> 295 | R6: =SUMIF($D$7:$D$126,"OK",R7:R126)+SUMIF($D$7:$D$126,"Parcial",R7:R126) -> 390 | S6: =SUMIF($D$7:$D$126,"OK",S7:S126)+SUMIF($D$7:$D$126,"Parcial",S7:S126) -> 705 | T6: =SUMIF($D$7:$D$126,"OK",T7:T126)+SUMIF($D$7:$D$126,"Parcial",T7:T126) -> 50 | U6: - | V6: =IF(F6=SUM(L6:T6),"OK","Diferente") -> OK | W6: =SUM(W7:W126) -> -1293.25
B7: Elpídio Gomes de Moura Neto | C7: 12 | D7: OK | E7: 140.44 | F7: =E7 -> 140.44 | G7: Pagamento único de R$ 445,81 | H7: Banco - Cora | L7: 76.43 | M7: 24.57 | N7: 13 | O7: 1.44 | P7: 5 | Q7: 5 | R7: 15 | V7: =IF(F7=SUM(L7:T7),"OK","Diferente") -> OK | W7: =IF(V7="Diferente",F7-SUM(L7:T7),"")
B8: Juliana Collyer Arruda de Moura | C8: 12 | D8: OK | E8: 101.29 | F8: =E8 -> 101.29 | H8: Banco - Cora | L8: 52.28 | M8: 24.57 | N8: 13 | O8: 1.44 | P8: 5 | Q8: 5 | V8: =IF(F8=SUM(L8:T8),"OK","Diferente") -> OK | W8: =IF(V8="Diferente",F8-SUM(L8:T8),"")
B9: Silvéria Lopes Vasconcelos Arruda | C9: 12 | D9: OK | E9: 91.29 | F9: =E9 -> 91.29 | H9: Banco - Cora | L9: 52.28 | M9: 24.57 | N9: 13 | O9: 1.44 | V9: =IF(F9=SUM(L9:T9),"OK","Diferente") -> OK | W9: =IF(V9="Diferente",F9-SUM(L9:T9),"")
B10: Francisco de Assis Vasconcelos Arruda | C10: 12 | D10: OK | E10: 112.79 | F10: =E10 -> 112.79 | H10: Banco - Cora | L10: 63.78 | M10: 24.57 | N10: 13 | O10: 1.44 | P10: 5 | Q10: 5 | V10: =IF(F10=SUM(L10:T10),"OK","Diferente") -> OK | W10: =IF(V10="Diferente",F10-SUM(L10:T10),"")
B11: Antônio Gonçalves de Lima Filho | C11: 11 | D11: OK | E11: 166.17 | F11: =E11 -> 166.17 | G11: Pagamento único de R$ 312,34 | H11: Banco - Cora | L11: 107.16 | M11: 24.57 | N11: 13 | O11: 1.44 | Q11: 10 | R11: 10 | V11: =IF(F11=SUM(L11:T11),"OK","Diferente") -> OK | W11: =IF(V11="Diferente",F11-SUM(L11:T11),"")
B12: Sandra Borges Gonçalves de Lima | C12: 11 | D12: OK | E12: 146.17 | F12: =E12 -> 146.17 | H12: Banco - Cora | L12: 107.16 | M12: 24.57 | N12: 13 | O12: 1.44 | V12: =IF(F12=SUM(L12:T12),"OK","Diferente") -> OK | W12: =IF(V12="Diferente",F12-SUM(L12:T12),"")
B13: Marcelo de Castro Brasil | D13: Pendente | E13: 296.49 | F13: 0 | L13: 127.48 | M13: 24.57 | N13: 13 | O13: 1.44 | P13: 10 | Q13: 20 | R13: 50 | S13: 50 | V13: =IF(F13=SUM(L13:T13),"OK","Diferente") -> Diferente | W13: =IF(V13="Diferente",F13-SUM(L13:T13),"") -> -296.49
B14: Flora Borges Gonçalves Lima Brasil | D14: Pendente | E14: 189.29 | F14: 0 | L14: 95.28 | M14: 24.57 | N14: 13 | O14: 1.44 | P14: 5 | S14: 50 | V14: =IF(F14=SUM(L14:T14),"OK","Diferente") -> Diferente | W14: =IF(V14="Diferente",F14-SUM(L14:T14),"") -> -189.29
B15: Cássio Pereira Costa Sousa | C15: 19 | D15: OK | E15: 186.14 | F15: =E15*2 -> 372.28 | G15: Pagamento único de R$ 564,26 descontado da despesa de alimentação paga pela C. Mônica referente à confraternização. Desta forma, não há essa entrada no extrato do banco. | H15: Banco - Cora | L15: =117.13+186.14 -> 303.27 | M15: 24.57 | N15: 13 | O15: 1.44 | P15: 5 | Q15: 5 | R15: 20 | V15: =IF(F15=SUM(L15:T15),"OK","Diferente") -> OK | W15: =IF(V15="Diferente",F15-SUM(L15:T15),"")
B16: Mônica de Araújo Campos Costa Sousa | C16: 19 | D16: OK | E16: 95.99 | F16: =E16*2 -> 191.98 | H16: Banco - Cora | L16: =46.98+95.99 -> 142.97 | M16: 24.57 | N16: 13 | O16: 1.44 | P16: 5 | Q16: 5 | V16: =IF(F16=SUM(L16:T16),"OK","Diferente") -> OK | W16: =IF(V16="Diferente",F16-SUM(L16:T16),"")
B17: José Maurício Guimarães Gomes | C17: 8 | D17: OK | E17: 192.19 | F17: =E17 -> 192.19 | G17: Pagamento único de R$ 324,18 | H17: Banco - Cora | L17: 148.18 | M17: 24.57 | N17: 13 | O17: 1.44 | P17: 5 | V17: =IF(F17=SUM(L17:T17),"OK","Diferente") -> OK | W17: =IF(V17="Diferente",F17-SUM(L17:T17),"")
B18: Ticiane Aragão da Silveira Gomes | C18: 8 | D18: OK | E18: 131.99 | F18: =E18 -> 131.99 | H18: Banco - Cora | L18: 92.98 | M18: 24.57 | N18: 13 | O18: 1.44 | V18: =IF(F18=SUM(L18:T18),"OK","Diferente") -> OK | W18: =IF(V18="Diferente",F18-SUM(L18:T18),"")
B19: Sérvulo Sidney Gladius Paiva Pimentel | C19: 1 | D19: OK | E19: 434.29 | F19: =E19 -> 434.29 | G19: Pagamento único de R$ 858,58 | H19: Banco - Cora | L19: 325.28 | M19: 24.57 | N19: 13 | O19: 11.44 | Q19: 10 | S19: 50 | V19: =IF(F19=SUM(L19:T19),"OK","Diferente") -> OK | W19: =IF(V19="Diferente",F19-SUM(L19:T19),"")
B20: Maria Danielly Rios da Silva Paiva | C20: 1 | D20: OK | E20: 424.29 | F20: =E20 -> 424.29 | H20: Banco - Cora | L20: 325.28 | M20: 24.57 | N20: 13 | O20: 1.44 | Q20: 10 | S20: 50 | V20: =IF(F20=SUM(L20:T20),"OK","Diferente") -> OK | W20: =IF(V20="Diferente",F20-SUM(L20:T20),"")
B21: Régis Bezerra Gomes | C21: 1 | D21: OK | E21: 171.99 | F21: =E21 -> 171.99 | G21: Pagamento único de R$ 315,58 | H21: Banco - Cora | L21: 92.98 | M21: 24.57 | N21: 13 | O21: 1.44 | P21: 5 | Q21: 5 | S21: 30 | V21: =IF(F21=SUM(L21:T21),"OK","Diferente") -> OK | W21: =IF(V21="Diferente",F21-SUM(L21:T21),"")
B22: Ana Carolina de Oliveira Martins Gomes | C22: 1 | D22: OK | E22: 143.59 | F22: =E22 -> 143.59 | H22: Banco - Cora | L22: 74.58 | M22: 24.57 | N22: 13 | O22: 1.44 | S22: 30 | V22: =IF(F22=SUM(L22:T22),"OK","Diferente") -> OK | W22: =IF(V22="Diferente",F22-SUM(L22:T22),"")
B23: Lindayana de Souza Florêncio | C23: 21 | D23: OK | E23: 83.34 | F23: =E23*2+50 -> 216.68 | G23: Não consta a entrada destes valores no banco pois foram utilizados para compensar a despesa do auto de natal no valor de R$ 445,56. Esta despesa compensa a mensalidade de dezembro/23 e janeiro/24. | H23: Banco - Cora | L23: =34.33*2 -> 68.66 | M23: =24.57*2 -> 49.14 | N23: 26 | O23: 2.88 | P23: 10 | Q23: 10 | T23: 50 | U23: Confraternização dezembro/23 (antecipado de janeiro). | V23: =IF(F23=SUM(L23:T23),"OK","Diferente") -> OK | W23: =IF(V23="Diferente",F23-SUM(L23:T23),"")
B24: Davi Florêncio de Sousa | C24: 21 | D24: OK | E24: 114.44 | F24: =E24*2 -> 228.88 | H24: Banco - Cora | L24: =50.43*2 -> 100.86 | M24: =24.57*2 -> 49.14 | N24: 26 | O24: 2.88 | P24: 10 | Q24: 10 | S24: 30 | V24: =IF(F24=SUM(L24:T24),"OK","Diferente") -> OK | W24: =IF(V24="Diferente",F24-SUM(L24:T24),"")
B25: Joaquim Garcez de Lima Rocha | D25: Pendente | E25: 160.4 | F25: 0 | L25: 106.39 | M25: 24.57 | N25: 13 | O25: 6.44 | Q25: 10 | V25: =IF(F25=SUM(L25:T25),"OK","Diferente") -> Diferente | W25: =IF(V25="Diferente",F25-SUM(L25:T25),"") -> -160.4
B26: Emília Mesquita Salgueiro Garcez | D26: Pendente | E26: 118.35 | F26: 0 | L26: 79.34 | M26: 24.57 | N26: 13 | O26: 1.44 | V26: =IF(F26=SUM(L26:T26),"OK","Diferente") -> Diferente | W26: =IF(V26="Diferente",F26-SUM(L26:T26),"") -> -118.35
B27: Francisco Saulo Studart Albuquerque | C27: 4 | D27: OK | E27: 150 | F27: 645 | G27: R$ 645 referente a agosto, setembro, outubro e novembro | H27: Banco - Cora | L27: =110.43+(645-150) -> 605.43 | M27: 24.57 | N27: 13 | O27: 2 | V27: =IF(F27=SUM(L27:T27),"OK","Diferente") -> OK | W27: =IF(V27="Diferente",F27-SUM(L27:T27),"")
B28: Franco Costa e Silva | C28: 18 | D28: OK | E28: 205.79 | F28: =E28 -> 205.79 | G28: Pagamento único de R$ 264,58. O valor foi a menor que o padrão da mensalidade pois no mês anterior foi realizado um pagamento a maior, gerando crédito para a mensalidade de dezembro. | H28: Banco - Cora | L28: =106.78-37 -> 69.78 | M28: 24.57 | N28: 13 | O28: 11.44 | P28: 5 | Q28: 5 | R28: 10 | S28: 30 | V28: =IF(F28=SUM(L28:T28),"OK","Diferente") -> Diferente | W28: =IF(V28="Diferente",F28-SUM(L28:T28),"") -> 37
B29: Juliana Soares Monteiro | C29: 18 | D29: Parcial | E29: 195.79 | F29: =264.58-F28 -> 58.79 | H29: Banco - Cora | L29: =106.78-100 -> 6.78 | M29: 24.57 | N29: 13 | O29: 1.44 | P29: 5 | Q29: 5 | R29: 10 | S29: 30 | V29: =IF(F29=SUM(L29:T29),"OK","Diferente") -> Diferente | W29: =IF(V29="Diferente",F29-SUM(L29:T29),"") -> -37
B30: Hugo Uchôa Passos Alencar | C30: 5 | D30: OK | E30: 207.69 | F30: =E30 -> 207.69 | G30: Pagamento único de R$ 364,38 | H30: Banco - Cora | L30: 113.68 | M30: 24.57 | N30: 13 | O30: 1.44 | P30: 5 | Q30: 10 | R30: 10 | S30: 30 | V30: =IF(F30=SUM(L30:T30),"OK","Diferente") -> OK | W30: =IF(V30="Diferente",F30-SUM(L30:T30),"")
B31: Mairi Alencar de Lacerda Ferraz Uchôa | C31: 5 | D31: OK | E31: 156.69 | F31: =E31 -> 156.69 | H31: Banco - Cora | L31: 67.68 | M31: 24.57 | N31: 13 | O31: 1.44 | Q31: 10 | R31: 10 | S31: 30 | V31: =IF(F31=SUM(L31:T31),"OK","Diferente") -> OK | W31: =IF(V31="Diferente",F31-SUM(L31:T31),"")
B32: João Carlos Studart Antero | D32: Pendente | E32: 123.99 | F32: 0 | L32: 69.98 | M32: 24.57 | N32: 13 | O32: 1.44 | P32: 5 | R32: 10 | V32: =IF(F32=SUM(L32:T32),"OK","Diferente") -> Diferente | W32: =IF(V32="Diferente",F32-SUM(L32:T32),"") -> -123.99
B33: Janaina Silva Leitão Studart Antero | D33: Pendente | E33: 118.99 | F33: 0 | L33: 69.98 | M33: 24.57 | N33: 13 | O33: 1.44 | R33: 10 | V33: =IF(F33=SUM(L33:T33),"OK","Diferente") -> Diferente | W33: =IF(V33="Diferente",F33-SUM(L33:T33),"") -> -118.99
B34: Janaina de Pádua Carneiro Vasconcelos Giffoni | C34: 12 | D34: OK | E34: 172.79 | F34: =E34 -> 172.79 | G34: Pagamento único de R$ 403,53 | H34: Banco - Cora | L34: 83.78 | M34: 24.57 | N34: 13 | O34: 1.44 | S34: 50 | V34: =IF(F34=SUM(L34:T34),"OK","Diferente") -> OK | W34: =IF(V34="Diferente",F34-SUM(L34:T34),"")
B35: Vicente Alves Giffoni | C35: 12 | D35: OK | E35: 230.74 | F35: =E35 -> 230.74 | H35: Banco - Cora | L35: 121.73 | M35: 24.57 | N35: 13 | O35: 11.44 | Q35: 10 | S35: 50 | V35: =IF(F35=SUM(L35:T35),"OK","Diferente") -> OK | W35: =IF(V35="Diferente",F35-SUM(L35:T35),"")
B36: Raphael Bruno Dantas Moreira | C36: 15 | D36: OK | E36: 196.2 | F36: =E36 -> 196.2 | H36: Banco - Cora | L36: 128.63 | M36: 24.57 | N36: 13 | O36: 10 | P36: 5 | Q36: 15 | V36: =IF(F36=SUM(L36:T36),"OK","Diferente") -> OK | W36: =IF(V36="Diferente",F36-SUM(L36:T36),"")
B37: Davi Silvino Moraes | C37: 2 | D37: OK | E37: 176.76 | F37: =E37 -> 176.76 | H37: Banco - Cora | L37: 79.19 | M37: 24.57 | N37: 13 | O37: 5 | P37: 5 | Q37: 10 | R37: 10 | S37: 30 | V37: =IF(F37=SUM(L37:T37),"OK","Diferente") -> OK | W37: =IF(V37="Diferente",F37-SUM(L37:T37),"")
B38: Dimaranje José Moraes | C38: 15 | D38: OK | E38: 110.81 | F38: =(271/2)+E38 -> 246.31 | G38: Pagamento único de R$ 271,00 referente a novembro. Pagamento único de R$ 221,62 referente a dezembro. | H38: Banco - Cora | L38: =71.74+135.5 -> 207.24 | M38: 24.57 | N38: 13 | O38: 1.5 | V38: =IF(F38=SUM(L38:T38),"OK","Diferente") -> OK | W38: =IF(V38="Diferente",F38-SUM(L38:T38),"")
B39: Silvane da Silva Gonçalves | C39: 15 | D39: OK | E39: 110.81 | F39: =(271/2)+E39 -> 246.31 | H39: Banco - Cora | L39: =71.74+135.5 -> 207.24 | M39: 24.57 | N39: 13 | O39: 1.5 | V39: =IF(F39=SUM(L39:T39),"OK","Diferente") -> OK | W39: =IF(V39="Diferente",F39-SUM(L39:T39),"")
B40: Vicente de Paula Giffoni Filho | C40: 1 | D40: OK | E40: 118.59 | F40: =E40 -> 118.59 | G40: Pagamento único de R$ 428,36 | H40: Banco - Cora | L40: 74.58 | M40: 24.57 | N40: 13 | O40: 1.44 | Q40: 5 | V40: =IF(F40=SUM(L40:T40),"OK","Diferente") -> OK | W40: =IF(V40="Diferente",F40-SUM(L40:T40),"")
B41: Francinete Alves de Oliveira Giffoni | C41: 1 | D41: OK | E41: 123.59 | F41: =E41 -> 123.59 | H41: Banco - Cora | L41: 74.58 | M41: 24.57 | N41: 13 | O41: 1.44 | P41: 5 | Q41: 5 | V41: =IF(F41=SUM(L41:T41),"OK","Diferente") -> OK | W41: =IF(V41="Diferente",F41-SUM(L41:T41),"")
B42: Emanuel Alves Giffoni | C42: 1 | D42: OK | E42: 118.59 | F42: =E42 -> 118.59 | H42: Banco - Cora | L42: 74.58 | M42: 24.57 | N42: 13 | O42: 1.44 | Q42: 5 | V42: =IF(F42=SUM(L42:T42),"OK","Diferente") -> OK | W42: =IF(V42="Diferente",F42-SUM(L42:T42),"")
...

Sheet 2023-DEZ-DESPESAS
B2: DESPESAS
B4: TOTAL | C4: - | D4: - | E4: =SUBTOTAL(9,E12,E37,E24,E105,E130,E136,E43,E6,E20,E192,E233,E142,E152,E162,E172,E182,E58) -> 0 | F4: =SUBTOTAL(9,F12,F37,F24,F95,F105,F130,F136,F43,F6,F20,F192,F233,F142,F152,F162,F172,F182,F58) -> 20359.32 | G4: - | H4: CAIXA | I4: COMPROVANTE | J4: PLANO DE CONTAS DG
C5: Data | D5: Efetivado | E5: Valor Previsto | F5: Valor Pago | G5: Observação
B6: NCL - Funcionários | C6: - | D6: - | E6: =SUM(E7:E11) -> 0 | F6: =SUM(F7:F11) -> 2464.52
B7: Salário | C7: 1 29 | D7: OK | E7: 0 | F7: =669.38+669.38 -> 1338.76 | G7: 01/12: Competência novembro, pago em dezembro. 29/12: Competência dezembro, pago em dezembro. | H7: Banco - Cora | I7: https://drive.google.com/file/d/1hy0gmUuDzO0Y1v2o5JeNrihBy4VZhOXk/view?usp=drive_link https://drive.google.com/file/d/1lH1HF_Pjg1fP995oUndkHiEUbdCEk4Lt/view?usp=drive_link
B8: 13° salário | C8: 20 | D8: OK | E8: 0 | F8: 325.99 | G8: 2a parcela 13° salário | H8: Banco - Cora | I8: https://drive.google.com/file/d/1HxfPZMes6T4DpkfQ9SN_bQakL0wH2ONT/view?usp=drive_link
B9: Férias | E9: 0 | F9: 0
B10: Encargos sociais | C10: 6 6 6 6 11 | D10: OK | E10: 0 | F10: =263.06+40.12+92.04+11.51+263.06 -> 669.79 | G10: 06/12: Darf previdenciário (R$ 263,06) 06/12: Darf previdenciário complementar (R$ 40,12) 06/12: FGTS (R$ 92,04) 06/12: PIS (R$ 11,51) 11/12: Darf previdenciário 13° salário (R$ 263,06) | H10: Banco - Cora | I10: https://drive.google.com/file/d/1K6wk-3aiUDrSIcQpIg07SrxvPGrFP-DY/view?usp=drive_link
B11: Outras despesas | C11: 22 | D11: OK | E11: 0 | F11: 129.98 | G11: 22/12: Duas cestas básicas para o Wesley. Dezembro/23 e janeiro/24. | H11: Banco - Cora | I11: https://drive.google.com/file/d/1armK0m59uAYu4CUS54qTVAiGc4D58WRv/view?usp=drive_link
B12: NCL - Repasses | C12: - | D12: - | E12: =SUM(E13:E19) -> 0 | F12: =SUM(F13:F19) -> 5194.16
B13: Diretoria Geral | C13: 20 | D13: OK | E13: 0 | F13: 2432.43 | H13: Banco - Prosperar Bank | I13: https://drive.google.com/file/d/1cArE6avLBdLZ_P5rT3rm_SHq9NEZyHHr/view?usp=drive_link
B14: 11a Região | C14: 14 | D14: OK | E14: 0 | F14: 1597 | H14: Banco - Prosperar Bank | I14: https://drive.google.com/file/d/16meczPDHPc1QEuGSscL4d7D707LYwmfm/view?usp=drive_link
B15: Novo Encanto | C15: 1 | D15: OK | E15: 0 | F15: 75 | H15: Banco - Cora | I15: https://drive.google.com/file/d/1cHkb8Yo3pPerc3nasiot9hJr4l1NKzRr/view?usp=drive_link
B16: Flor Divina | C16: 29 | D16: OK | E16: 0 | F16: =1089.73 -> 1089.73 | G16: Realizada uma transferência única de R$ 1.134,87, tendo R$ 1.089,73 saído do caixa da tesouraria e R$ 45,14 saído do caixa do Plantio (este valor está registrado nas despesas do plantio). | H16: Banco - Cora | I16: https://drive.google.com/file/d/1Ze8pvPmSyC-jJebtaDGmWRAVg1EjtwxZ/view?usp=drive_link
B17: Outro repasse (1) | E17: 0 | F17: 0
B18: Outro repasse (2) | E18: 0 | F18: 0
B19: Outro repasse (3) | E19: 0 | F19: 0
B20: NCL - Tarifas bancárias | C20: - | D20: - | E20: =SUM(E21:E23) -> 0 | F20: =SUM(F21:F23) -> 185.83
B21: Tarifa Itaú | C21: 4 | D21: OK | E21: 0 | F21: 118 | H21: Banco - Itaú | I21: https://drive.google.com/file/d/1Lrvz77hCs-9Ap-_hYtGDYxki1G3ANRlg/view?usp=drive_link
B22: IR do rendimento bruto do Pagbank | C22: 3 a 23 | D22: OK | E22: 0 | F22: 67.83 | H22: Banco - Pagbank | I22: https://drive.google.com/file/d/11LttsR061P4v40YjP52xj6kuSFCfOTYi/view?usp=drive_link
B23: Tarifa 3 | E23: 0 | F23: 0
B24: NCL - Despesas gerais | C24: - | D24: - | E24: =SUM(E25:E36) -> 0 | F24: =SUM(F25:F36) -> 4146.94
B25: Energia Elétrica | C25: 20 | D25: OK | E25: 0 | F25: 990.95 | H25: Banco - Prosperar Bank | I25: https://drive.google.com/file/d/19M0xZrZjCQjoBB2X8KbSUNgdb2ElEME8/view?usp=sharing
B26: Vigilância - Banco | C26: 17 | D26: OK | E26: 0 | F26: =590 -> 590 | G26: 17/12: R$ 590 referente a 2a escala. | H26: Banco - Cora | I26: https://drive.google.com/file/d/1-wYPjr9-RuWpx8mwPbBKgbEW_-ao1nJ2/view?usp=drive_link
B27: Contabilidade | C27: 4 | D27: OK | E27: 0 | F27: 396 | H27: Banco - Cora | I27: https://drive.google.com/file/d/1upTOtwJrjO-9QEwX0pEf6Xu4dDw0VTRX/view?usp=drive_link
B28: Internet | C28: 1 | D28: OK | E28: 0 | F28: 79.99 | H28: Banco - Cora | I28: https://drive.google.com/file/d/154fyTE2hE2-eF-mYvbl4PsFrIA4CvEBh/view?usp=drive_link
B29: Som | E29: 0 | F29: 0
B30: Jardim | E30: 0 | F30: 0
B31: Aluguel cadeiras 2a escala e sessão extra M. Herculano | C31: 18 | D31: OK | E31: 0 | F31: 200 | H31: Banco - Cora | I31: https://drive.google.com/file/d/1XNnx8OvJv3e9g5t7kDyG_22UT3Gy9hE9/view?usp=drive_link
B32: Compra de calças brancas e amarelas M. Herculano | C32: 19 | D32: OK | E32: 0 | F32: 800 | H32: Banco - Cora | I32: https://drive.google.com/file/d/1I6z53UUGdn_2WHC0Wbf8Uboov-m0h4Gh/view?usp=drive_link
B33: Homenagem M. Herculano | C33: 21 | D33: OK | E33: 0 | F33: 290 | H33: Banco - Cora | I33: https://drive.google.com/file/d/1jqskAC3ezP8yULTHgRoYQmbM6N641kMA/view?usp=drive_link
B34: Vigilância - Espécie | C34: 31 | D34: OK | E34: 0 | F34: 800 | G34: 31/12: R$ 800 referente a sessão de ano novo. | H34: Dinheiro em espécie | I34: https://drive.google.com/file/d/1P-zr1Ezy8pcmrVnt_qoETRI434kGz9Bv/view?usp=drive_link
B35: Despesa 5 | E35: 0 | F35: 0
B36: Despesa 6 | E36: 0 | F36: 0
B37: NCL - Organ | C37: - | D37: - | E37: =SUM(E38:E42) -> 0 | F37: =SUM(F38:F42) -> 2855.32
B38: Mercado | C38: 2 15 17 17 17 22 | D38: OK | E38: 0 | F38: =194.36+323.77+99+51.76+195.87+60 -> 924.76 | G38: 02/12: Despesa lanche compras realizadas pela C. Ticiane (R$ 194,36) 15/12: Despesa lanche compras realizadas pela C. Mônica (R$ 323,77) 17/12: Despesa sucos realizadas pela C. Mônica (R$ 99,00) 17/12: Despesa pães realizadas pela C. Mônica (R$ 51,76) 17/12: Despesa lanche pós sessão realizadas pela C. Mônica (R$ 195,87) 22/12: Despesa milhos realizada pela Genilda (R$ 60,00). Valor compensado em gasolina. | H38: Banco - Cora | I38: https://drive.google.com/file/d/1qohA5ZqkXdAGAMBL9jPLCmu8490VWIKK/view?usp=drive_link https://drive.google.com/file/d/1FimwTgXc5cQaAAXqpNbxTZQ5KHiZTdnC/view?usp=drive_link https://drive.google.com/file/d/1UxUwTwLslc6eMcGDWQDeEAC7cY_apPPj/view?usp=drive_link https://drive.google.com/file/d/1FVP9SX6TRCPgAC27SHwM1qTxya69rkaN/view?usp=drive_link https://drive.google.com/file/d/1vbz-0wRkX3s6zyqn-g6Mu60pchC2vKN3/view?usp=drive_link https://drive.google.com/file/d/1NpttEIh0DeYQy-fFYDCiY2BOfVJw1uMu/view?usp=drive_link
B39: Água mineral | C39: 6 | D39: OK | E39: 0 | F39: =176 -> 176 | G39: 06/12: Compra de água mineral realizada pela C. Mônica (R$ 176,00) | H39: Banco - Prosperar Bank | I39: https://drive.google.com/file/d/1_jNZMYCrAGGWzhMBq9-LhIw9GpW9Czv-/view?usp=drive_link
B40: Jantar | C40: 1 2 15 | D40: OK | E40: 0 | F40: =344.38+54.52+471.89+35.94 -> 906.73 | G40: 01/12: Despesa jantar compras realizadas pela Janaina (R$ 344,38) 02/12: Despesa jantar compras realizadas pela Janaina (R$ 54,52) 15/12: Despesa jantar compras realizadas pela C. Mônica (R$ 471,89) 18/12: Despesa jantar compras realizadas pela C. Mônica (R$ 35,94) | H40: Banco - Cora | I40: https://drive.google.com/file/d/1nPgegJSuqnwuk-iYFRhXYHo8wTC8aEz9/view?usp=drive_link https://drive.google.com/file/d/1sRWeeKtrGlKQTITRH-yqV0m_hkcXNgii/view?usp=drive_link https://drive.google.com/file/d/1x9MFphbftZkHDMhlobbkfb6HuGUDHzNt/view?usp=drive_link https://drive.google.com/file/d/1zRm9goP6Ggpm_QObPvcdrIUpZEEYidEP/view?usp=drive_link
B41: Material de limpeza | C41: 3 5 15 30 | D41: OK | E41: 0 | F41: =40+345.8+173.44+243.6+9.99 -> 812.83 | G41: 03/12: Material de limpeza compras realizadas pelo Didi (R$ 40,00) 05/12: Material de limpeza compras realizadas pela C. Mônica (R$ 345,80) 15/12: Material de limpeza compras realizadas pela C. Mônica (R$ 173,44) 30/12: Material de limpeza compras realizadas pela C. Mônica (R$ 243,60 + R$ 9,99) | H41: Banco - Cora | I41: https://drive.google.com/file/d/1xJLqU67vj9QoDtu5M4sDg3TwvPlUd5Sp/view?usp=drive_link https://drive.google.com/file/d/12kj-Bqazy502velNLugU1ASuF7W7G2mr/view?usp=drive_link https://drive.google.com/file/d/1puaDbpAwNB8jJhxFDy9XPv-19RGucxbz/view?usp=drive_link https://drive.google.com/file/d/1XJXpsoBSrRqg7Yb5ZjlIUeaILjYtuxrx/view?usp=drive_link
B42: Outra despesa (3) | C42: 31 | D42: OK | E42: 0 | F42: 35 | G42: 31/12: Despesa castanhas pós sessão realizada pela C. Mônica (R$ 35,00) | H42: Dinheiro em espécie | I42: https://drive.google.com/file/d/1-8_zDpcbXg1Q9ElAhbCwiAwIGBZzl8r3/view?usp=drive_link
...

Sheet JAN-Receitas
B2: RECEITAS
B4: TOTAL | E4: =SUM(E6,E127,E148,E168,E172) -> 17447.43 | F4: =SUM(F6,F127,F148,F168,F172) -> 49292.99 | H4: CAIXA | I4: PLANO DE CONTAS DG
C5: Data | D5: Efetivado | E5: Valor Previsto | F5: Valor Recebido | G5: Observação | J5: Inadimp. (qtd) | K5: Inadimp. (R$) | L5: % Atraso | M5: Núcleo | N5: Repasse DG | O5: Repasse 11a R | P5: Benef. NLT | Q5: NE NLT | R5: Plantio NLT | S5: FR Bilhete Aéreo | T5: FR Construção | U5: Taxa Extra | V5: Detalhamento Taxa Extra | X5: A receber:
B6: Mensalidade | C6: 10 | D6: - | E6: =SUM(E7:E126) -> 17447.43 | F6: =SUMIF(D7:D126,"OK",F7:F126)+SUMIF(D7:D126,"Parcial",F7:F126) -> 13383.98 | G6: - | J6: =(COUNTIF(D7:D126,"Pendente")+COUNTIF(D7:D126,"Parcial"))/COUNTA(B7:B126) -> 0.31632653 | K6: =IFERROR(-(X6/E6),"Pendente info") -> 0.25623029 | L6: =SUM(L7:L105)/COUNTA(B7:B105) -> 0.19387755 | M6: =SUMIF($D$7:$D$126,"OK",M7:M126)+SUMIF($D$7:$D$126,"Parcial",M7:M126) -> 7065 | N6: =SUMIF($D$7:$D$126,"OK",N7:N126)+SUMIF($D$7:$D$126,"Parcial",N7:N126) -> 1621.62 | O6: =SUMIF($D$7:$D$126,"OK",O7:O126)+SUMIF($D$7:$D$126,"Parcial",O7:O126) -> 792 | P6: =SUMIF($D$7:$D$126,"OK",P7:P126)+SUMIF($D$7:$D$126,"Parcial",P7:P126) -> 152.36 | Q6: =SUMIF($D$7:$D$126,"OK",Q7:Q126)+SUMIF($D$7:$D$126,"Parcial",Q7:Q126) -> 155 | R6: =SUMIF($D$7:$D$126,"OK",R7:R126)+SUMIF($D$7:$D$126,"Parcial",R7:R126) -> 185 | S6: =SUMIF($D$7:$D$126,"OK",S7:S126)+SUMIF($D$7:$D$126,"Parcial",S7:S126) -> 217 | T6: =SUMIF($D$7:$D$126,"OK",T7:T126)+SUMIF($D$7:$D$126,"Parcial",T7:T126) -> 580 | U6: =SUMIF($D$7:$D$126,"OK",U7:U126)+SUMIF($D$7:$D$126,"Parcial",U7:U126) -> 2616 | V6: - | W6: =IF(F6=SUM(M6:U6),"OK","Diferente") -> OK | X6: =SUM(X7:X126) -> -4470.56
B7: ELPÍDIO GOMES DE MOURA NETO | D7: OK | E7: =SUM(M7:U7) -> 0 | L7: =IF(C7>=13,1,"") | V7: TAXA CONFRATERNIZAÇÃO 2024 R$ 5,00; TAXA DE PREPARO 1/2 R$ 13,00 | W7: =IF(F7=SUM(M7:U7),"OK","Diferente") -> OK | X7: =IF(W7="Diferente",F7-SUM(M7:U7),"")
B8: JULIANA COLLYER ARRUDA DE MOURA | D8: OK | E8: =SUM(M8:U8) -> 0 | L8: =IF(C8>=13,1,"") | V8: TAXA CONFRATERNIZAÇÃO 2024 R$ 5,00; TAXA DE PREPARO 1/2 R$ 13,00 | W8: =IF(F8=SUM(M8:U8),"OK","Diferente") -> OK | X8: =IF(W8="Diferente",F8-SUM(M8:U8),"")
B9: SILVERIA LOPES VASCONCELOS ARRUDA | D9: OK | E9: =SUM(M9:U9) -> 0 | L9: =IF(C9>=13,1,"") | V9: TAXA CONFRATERNIZAÇÃO 2024 R$ 5,00; TAXA DE PREPARO 1/2 R$ 13,00 | W9: =IF(F9=SUM(M9:U9),"OK","Diferente") -> OK | X9: =IF(W9="Diferente",F9-SUM(M9:U9),"")
B10: FRANCISCO DE ASSIS VASCONCELOS ARRUDA | D10: OK | E10: =SUM(M10:U10) -> 0 | L10: =IF(C10>=13,1,"") | V10: TAXA CONFRATERNIZAÇÃO 2024 R$ 5,00; TAXA DE PREPARO 1/2 R$ 13,00 | W10: =IF(F10=SUM(M10:U10),"OK","Diferente") -> OK | X10: =IF(W10="Diferente",F10-SUM(M10:U10),"")
B11: ANTÔNIO GONÇALVES DE LIMA FILHO | C11: 10 | D11: OK | E11: =SUM(M11:U11) -> 193.43 | F11: =E11 -> 193.43 | H11: Banco - Cora | L11: =IF(C11>=13,1,"") | M11: 130 | N11: 24.57 | O11: 12 | P11: 3.86 | Q11: 5 | U11: 18 | V11: TAXA CONFRATERNIZAÇÃO 2024 R$ 5,00; TAXA DE PREPARO 1/2 R$ 13,00 | W11: =IF(F11=SUM(M11:U11),"OK","Diferente") -> OK | X11: =IF(W11="Diferente",F11-SUM(M11:U11),"")
B12: SANDRA BORGES GONÇALVES DE LIMA | C12: 10 | D12: OK | E12: =SUM(M12:U12) -> 186.57 | F12: =E12 -> 186.57 | H12: Banco - Cora | L12: =IF(C12>=13,1,"") | M12: 130 | N12: 24.57 | O12: 12 | P12: 2 | U12: 18 | V12: TAXA CONFRATERNIZAÇÃO 2024 R$ 5,00; TAXA DE PREPARO 1/2 R$ 13,00 | W12: =IF(F12=SUM(M12:U12),"OK","Diferente") -> OK | X12: =IF(W12="Diferente",F12-SUM(M12:U12),"")
B13: MARCELO DE CASTRO BRASIL | D13: Pendente | E13: =SUM(M13:U13) -> 366.49 | L13: =IF(C13>=13,1,"") | M13: 130.48 | N13: 24.57 | O13: 12 | P13: 1.44 | Q13: 10 | R13: 20 | S13: 50 | T13: 50 | U13: 68 | V13: COMPRA DE ARCONDICIONADO 7/10 R$ 50,00; TAXA CONFRATERNIZAÇÃO 2024 R$ 5,00; TAXA DE PREPARO 1/2 R$ 13,00 | W13: =IF(F13=SUM(M13:U13),"OK","Diferente") -> Diferente | X13: =IF(W13="Diferente",F13-SUM(M13:U13),"") -> -366.49
B14: FLORA BORGES GONÇALVES LIMA BRASIL | D14: Pendente | E14: =SUM(M14:U14) -> 209.29 | L14: =IF(C14>=13,1,"") | M14: 98.28 | N14: 24.57 | O14: 12 | P14: 1.44 | Q14: 5 | T14: 50 | U14: 18 | V14: TAXA CONFRATERNIZAÇÃO 2024 R$ 5,00; TAXA DE PREPARO 1/2 R$ 13,00 | W14: =IF(F14=SUM(M14:U14),"OK","Diferente") -> Diferente | X14: =IF(W14="Diferente",F14-SUM(M14:U14),"") -> -209.29
B15: CÁSSIO PEREIRA COSTA SOUSA | D15: Pendente | E15: =SUM(M15:U15) -> 316.14 | L15: =IF(C15>=13,1,"") | M15: 180.13 | N15: 24.57 | O15: 12 | P15: 1.44 | Q15: 5 | R15: 5 | S15: 20 | U15: 68 | V15: COMPRA DE ARCONDICIONADO 7/10 R$ 50,00; TAXA CONFRATERNIZAÇÃO 2024 R$ 5,00; TAXA DE PREPARO 1/2 R$ 13,00 | W15: =IF(F15=SUM(M15:U15),"OK","Diferente") -> Diferente | X15: =IF(W15="Diferente",F15-SUM(M15:U15),"") -> -316.14
B16: MÔNICA DE ARAUJO CAMPOS COSTA SOUSA | D16: Pendente | E16: =SUM(M16:U16) -> 155.99 | L16: =IF(C16>=13,1,"") | M16: 89.98 | N16: 24.57 | O16: 12 | P16: 1.44 | Q16: 5 | R16: 5 | U16: 18 | V16: TAXA CONFRATERNIZAÇÃO 2024 R$ 5,00; TAXA DE PREPARO 1/2 R$ 13,00 | W16: =IF(F16=SUM(M16:U16),"OK","Diferente") -> Diferente | X16: =IF(W16="Diferente",F16-SUM(M16:U16),"") -> -155.99
B17: JOSÉ MAURÍCIO GUIMARÃES GOMES | C17: 10 | D17: OK | E17: =SUM(M17:U17) -> 252.19 | F17: =E17 -> 252.19 | H17: Banco - Cora | L17: =IF(C17>=13,1,"") | M17: 191.18 | N17: 24.57 | O17: 12 | P17: 1.44 | Q17: 5 | U17: 18 | V17: TAXA CONFRATERNIZAÇÃO 2024 R$ 5,00; TAXA DE PREPARO 1/2 R$ 13,00 | W17: =IF(F17=SUM(M17:U17),"OK","Diferente") -> OK | X17: =IF(W17="Diferente",F17-SUM(M17:U17),"")
B18: TICIANE ARAGAO DA SILVEIRA GOMES | C18: 10 | D18: OK | E18: =SUM(M18:U18) -> 191.99 | F18: =E18 -> 191.99 | H18: Banco - Cora | L18: =IF(C18>=13,1,"") | M18: 135.98 | N18: 24.57 | O18: 12 | P18: 1.44 | U18: 18 | V18: TAXA CONFRATERNIZAÇÃO 2024 R$ 5,00; TAXA DE PREPARO 1/2 R$ 13,00 | W18: =IF(F18=SUM(M18:U18),"OK","Diferente") -> OK | X18: =IF(W18="Diferente",F18-SUM(M18:U18),"")
B19: SERVULO SIDNEY GLADIUS PAIVA PIMENTEL | C19: 9 | D19: OK | E19: =SUM(M19:U19) -> 459.29 | F19: =E19 -> 459.29 | H19: Banco - Cora | L19: =IF(C19>=13,1,"") | M19: 328.28 | N19: 24.57 | O19: 12 | P19: 11.44 | Q19: 5 | R19: 10 | T19: 50 | U19: 18 | V19: TAXA CONFRATERNIZAÇÃO 2024 R$ 5,00; TAXA DE PREPARO 1/2 R$ 13,00 | W19: =IF(F19=SUM(M19:U19),"OK","Diferente") -> OK | X19: =IF(W19="Diferente",F19-SUM(M19:U19),"")
B20: MARIA DANIELLY RIOS DA SILVA PAIVA | C20: 9 | D20: OK | E20: =SUM(M20:U20) -> 449.29 | F20: =E20 -> 449.29 | H20: Banco - Cora | L20: =IF(C20>=13,1,"") | M20: 328.28 | N20: 24.57 | O20: 12 | P20: 1.44 | Q20: 5 | R20: 10 | T20: 50 | U20: 18 | V20: TAXA CONFRATERNIZAÇÃO 2024 R$ 5,00; TAXA DE PREPARO 1/2 R$ 13,00 | W20: =IF(F20=SUM(M20:U20),"OK","Diferente") -> OK | X20: =IF(W20="Diferente",F20-SUM(M20:U20),"")
B21: RÉGIS BEZERRA GOMES | C21: 11 | D21: OK | E21: =SUM(M21:U21) -> 266.99 | F21: =E21 -> 266.99 | H21: Banco - Cora | L21: =IF(C21>=13,1,"") | M21: 120.98 | N21: 24.57 | O21: 12 | P21: 1.44 | Q21: 5 | R21: 5 | T21: 30 | U21: 68 | V21: COMPRA DE ARCONDICIONADO 7/10 R$ 50,00; TAXA CONFRATERNIZAÇÃO 2024 R$ 5,00; TAXA DE PREPARO 1/2 R$ 13,00 | W21: =IF(F21=SUM(M21:U21),"OK","Diferente") -> OK | X21: =IF(W21="Diferente",F21-SUM(M21:U21),"")
